Traceback (most recent call last):
  File "/home/bs/python-scripts/telegram-bot/bot.py", line 1, in <module>
    from telegram import Update
ModuleNotFoundError: No module named 'telegram'
/home/bs/.virtualenvs/telegram/lib/python3.10/site-packages/pydub/utils.py:170: RuntimeWarning: Couldn't find ffmpeg or avconv - defaulting to ffmpeg, but may not work
  warn("Couldn't find ffmpeg or avconv - defaulting to ffmpeg, but may not work", RuntimeWarning)
/home/bs/.virtualenvs/telegram/lib/python3.10/site-packages/pydub/utils.py:170: RuntimeWarning: Couldn't find ffmpeg or avconv - defaulting to ffmpeg, but may not work
  warn("Couldn't find ffmpeg or avconv - defaulting to ffmpeg, but may not work", RuntimeWarning)
/home/bs/.virtualenvs/telegram/lib/python3.10/site-packages/pydub/utils.py:170: RuntimeWarning: Couldn't find ffmpeg or avconv - defaulting to ffmpeg, but may not work
  warn("Couldn't find ffmpeg or avconv - defaulting to ffmpeg, but may not work", RuntimeWarning)
Error while getting Updates: Conflict: terminated by other getUpdates request; make sure that only one bot instance is running
No error handlers are registered, logging exception.
Traceback (most recent call last):
  File "/home/bs/.virtualenvs/telegram/lib/python3.10/site-packages/telegram/ext/_updater.py", line 600, in _network_loop_retry
    if not await action_cb():
  File "/home/bs/.virtualenvs/telegram/lib/python3.10/site-packages/telegram/ext/_updater.py", line 327, in polling_action_cb
    raise exc
  File "/home/bs/.virtualenvs/telegram/lib/python3.10/site-packages/telegram/ext/_updater.py", line 312, in polling_action_cb
    updates = await self.bot.get_updates(
  File "/home/bs/.virtualenvs/telegram/lib/python3.10/site-packages/telegram/ext/_extbot.py", line 524, in get_updates
    updates = await super().get_updates(
  File "/home/bs/.virtualenvs/telegram/lib/python3.10/site-packages/telegram/_bot.py", line 334, in decorator
    result = await func(*args, **kwargs)  # skipcq: PYL-E1102
  File "/home/bs/.virtualenvs/telegram/lib/python3.10/site-packages/telegram/_bot.py", line 3584, in get_updates
    await self._post(
  File "/home/bs/.virtualenvs/telegram/lib/python3.10/site-packages/telegram/_bot.py", line 422, in _post
    return await self._do_post(
  File "/home/bs/.virtualenvs/telegram/lib/python3.10/site-packages/telegram/ext/_extbot.py", line 306, in _do_post
    return await super()._do_post(
  File "/home/bs/.virtualenvs/telegram/lib/python3.10/site-packages/telegram/_bot.py", line 453, in _do_post
    return await request.post(
  File "/home/bs/.virtualenvs/telegram/lib/python3.10/site-packages/telegram/request/_baserequest.py", line 165, in post
    result = await self._request_wrapper(
  File "/home/bs/.virtualenvs/telegram/lib/python3.10/site-packages/telegram/request/_baserequest.py", line 330, in _request_wrapper
    raise Conflict(message)
telegram.error.Conflict: Conflict: terminated by other getUpdates request; make sure that only one bot instance is running
Error while getting Updates: Conflict: terminated by other getUpdates request; make sure that only one bot instance is running
No error handlers are registered, logging exception.
Traceback (most recent call last):
  File "/home/bs/.virtualenvs/telegram/lib/python3.10/site-packages/telegram/ext/_updater.py", line 600, in _network_loop_retry
    if not await action_cb():
  File "/home/bs/.virtualenvs/telegram/lib/python3.10/site-packages/telegram/ext/_updater.py", line 327, in polling_action_cb
    raise exc
  File "/home/bs/.virtualenvs/telegram/lib/python3.10/site-packages/telegram/ext/_updater.py", line 312, in polling_action_cb
    updates = await self.bot.get_updates(
  File "/home/bs/.virtualenvs/telegram/lib/python3.10/site-packages/telegram/ext/_extbot.py", line 524, in get_updates
    updates = await super().get_updates(
  File "/home/bs/.virtualenvs/telegram/lib/python3.10/site-packages/telegram/_bot.py", line 334, in decorator
    result = await func(*args, **kwargs)  # skipcq: PYL-E1102
  File "/home/bs/.virtualenvs/telegram/lib/python3.10/site-packages/telegram/_bot.py", line 3584, in get_updates
    await self._post(
  File "/home/bs/.virtualenvs/telegram/lib/python3.10/site-packages/telegram/_bot.py", line 422, in _post
    return await self._do_post(
  File "/home/bs/.virtualenvs/telegram/lib/python3.10/site-packages/telegram/ext/_extbot.py", line 306, in _do_post
    return await super()._do_post(
  File "/home/bs/.virtualenvs/telegram/lib/python3.10/site-packages/telegram/_bot.py", line 453, in _do_post
    return await request.post(
  File "/home/bs/.virtualenvs/telegram/lib/python3.10/site-packages/telegram/request/_baserequest.py", line 165, in post
    result = await self._request_wrapper(
  File "/home/bs/.virtualenvs/telegram/lib/python3.10/site-packages/telegram/request/_baserequest.py", line 330, in _request_wrapper
    raise Conflict(message)
telegram.error.Conflict: Conflict: terminated by other getUpdates request; make sure that only one bot instance is running
Error while getting Updates: Conflict: terminated by other getUpdates request; make sure that only one bot instance is running
No error handlers are registered, logging exception.
Traceback (most recent call last):
  File "/home/bs/.virtualenvs/telegram/lib/python3.10/site-packages/telegram/ext/_updater.py", line 600, in _network_loop_retry
    if not await action_cb():
  File "/home/bs/.virtualenvs/telegram/lib/python3.10/site-packages/telegram/ext/_updater.py", line 327, in polling_action_cb
    raise exc
  File "/home/bs/.virtualenvs/telegram/lib/python3.10/site-packages/telegram/ext/_updater.py", line 312, in polling_action_cb
    updates = await self.bot.get_updates(
  File "/home/bs/.virtualenvs/telegram/lib/python3.10/site-packages/telegram/ext/_extbot.py", line 524, in get_updates
    updates = await super().get_updates(
  File "/home/bs/.virtualenvs/telegram/lib/python3.10/site-packages/telegram/_bot.py", line 334, in decorator
    result = await func(*args, **kwargs)  # skipcq: PYL-E1102
  File "/home/bs/.virtualenvs/telegram/lib/python3.10/site-packages/telegram/_bot.py", line 3584, in get_updates
    await self._post(
  File "/home/bs/.virtualenvs/telegram/lib/python3.10/site-packages/telegram/_bot.py", line 422, in _post
    return await self._do_post(
  File "/home/bs/.virtualenvs/telegram/lib/python3.10/site-packages/telegram/ext/_extbot.py", line 306, in _do_post
    return await super()._do_post(
  File "/home/bs/.virtualenvs/telegram/lib/python3.10/site-packages/telegram/_bot.py", line 453, in _do_post
    return await request.post(
  File "/home/bs/.virtualenvs/telegram/lib/python3.10/site-packages/telegram/request/_baserequest.py", line 165, in post
    result = await self._request_wrapper(
  File "/home/bs/.virtualenvs/telegram/lib/python3.10/site-packages/telegram/request/_baserequest.py", line 330, in _request_wrapper
    raise Conflict(message)
telegram.error.Conflict: Conflict: terminated by other getUpdates request; make sure that only one bot instance is running
Error while getting Updates: Conflict: terminated by other getUpdates request; make sure that only one bot instance is running
No error handlers are registered, logging exception.
Traceback (most recent call last):
  File "/home/bs/.virtualenvs/telegram/lib/python3.10/site-packages/telegram/ext/_updater.py", line 600, in _network_loop_retry
    if not await action_cb():
  File "/home/bs/.virtualenvs/telegram/lib/python3.10/site-packages/telegram/ext/_updater.py", line 327, in polling_action_cb
    raise exc
  File "/home/bs/.virtualenvs/telegram/lib/python3.10/site-packages/telegram/ext/_updater.py", line 312, in polling_action_cb
    updates = await self.bot.get_updates(
  File "/home/bs/.virtualenvs/telegram/lib/python3.10/site-packages/telegram/ext/_extbot.py", line 524, in get_updates
    updates = await super().get_updates(
  File "/home/bs/.virtualenvs/telegram/lib/python3.10/site-packages/telegram/_bot.py", line 334, in decorator
    result = await func(*args, **kwargs)  # skipcq: PYL-E1102
  File "/home/bs/.virtualenvs/telegram/lib/python3.10/site-packages/telegram/_bot.py", line 3584, in get_updates
    await self._post(
  File "/home/bs/.virtualenvs/telegram/lib/python3.10/site-packages/telegram/_bot.py", line 422, in _post
    return await self._do_post(
  File "/home/bs/.virtualenvs/telegram/lib/python3.10/site-packages/telegram/ext/_extbot.py", line 306, in _do_post
    return await super()._do_post(
  File "/home/bs/.virtualenvs/telegram/lib/python3.10/site-packages/telegram/_bot.py", line 453, in _do_post
    return await request.post(
  File "/home/bs/.virtualenvs/telegram/lib/python3.10/site-packages/telegram/request/_baserequest.py", line 165, in post
    result = await self._request_wrapper(
  File "/home/bs/.virtualenvs/telegram/lib/python3.10/site-packages/telegram/request/_baserequest.py", line 330, in _request_wrapper
    raise Conflict(message)
telegram.error.Conflict: Conflict: terminated by other getUpdates request; make sure that only one bot instance is running
Error while getting Updates: Conflict: terminated by other getUpdates request; make sure that only one bot instance is running
No error handlers are registered, logging exception.
Traceback (most recent call last):
  File "/home/bs/.virtualenvs/telegram/lib/python3.10/site-packages/telegram/ext/_updater.py", line 600, in _network_loop_retry
    if not await action_cb():
  File "/home/bs/.virtualenvs/telegram/lib/python3.10/site-packages/telegram/ext/_updater.py", line 327, in polling_action_cb
    raise exc
  File "/home/bs/.virtualenvs/telegram/lib/python3.10/site-packages/telegram/ext/_updater.py", line 312, in polling_action_cb
    updates = await self.bot.get_updates(
  File "/home/bs/.virtualenvs/telegram/lib/python3.10/site-packages/telegram/ext/_extbot.py", line 524, in get_updates
    updates = await super().get_updates(
  File "/home/bs/.virtualenvs/telegram/lib/python3.10/site-packages/telegram/_bot.py", line 334, in decorator
    result = await func(*args, **kwargs)  # skipcq: PYL-E1102
  File "/home/bs/.virtualenvs/telegram/lib/python3.10/site-packages/telegram/_bot.py", line 3584, in get_updates
    await self._post(
  File "/home/bs/.virtualenvs/telegram/lib/python3.10/site-packages/telegram/_bot.py", line 422, in _post
    return await self._do_post(
  File "/home/bs/.virtualenvs/telegram/lib/python3.10/site-packages/telegram/ext/_extbot.py", line 306, in _do_post
    return await super()._do_post(
  File "/home/bs/.virtualenvs/telegram/lib/python3.10/site-packages/telegram/_bot.py", line 453, in _do_post
    return await request.post(
  File "/home/bs/.virtualenvs/telegram/lib/python3.10/site-packages/telegram/request/_baserequest.py", line 165, in post
    result = await self._request_wrapper(
  File "/home/bs/.virtualenvs/telegram/lib/python3.10/site-packages/telegram/request/_baserequest.py", line 330, in _request_wrapper
    raise Conflict(message)
telegram.error.Conflict: Conflict: terminated by other getUpdates request; make sure that only one bot instance is running
/home/bs/.virtualenvs/telegram/lib/python3.10/site-packages/pydub/utils.py:170: RuntimeWarning: Couldn't find ffmpeg or avconv - defaulting to ffmpeg, but may not work
  warn("Couldn't find ffmpeg or avconv - defaulting to ffmpeg, but may not work", RuntimeWarning)
Traceback (most recent call last):
  File "/home/bs/python-scripts/telegram-bot/bot.py", line 1, in <module>
    from telegram import Update
ModuleNotFoundError: No module named 'telegram'
/home/bs/.virtualenvs/telegram/lib/python3.10/site-packages/pydub/utils.py:170: RuntimeWarning: Couldn't find ffmpeg or avconv - defaulting to ffmpeg, but may not work
  warn("Couldn't find ffmpeg or avconv - defaulting to ffmpeg, but may not work", RuntimeWarning)
Error while getting Updates: Bad Gateway
No error handlers are registered, logging exception.
Traceback (most recent call last):
  File "/home/bs/.virtualenvs/telegram/lib/python3.10/site-packages/telegram/ext/_updater.py", line 600, in _network_loop_retry
    if not await action_cb():
  File "/home/bs/.virtualenvs/telegram/lib/python3.10/site-packages/telegram/ext/_updater.py", line 327, in polling_action_cb
    raise exc
  File "/home/bs/.virtualenvs/telegram/lib/python3.10/site-packages/telegram/ext/_updater.py", line 312, in polling_action_cb
    updates = await self.bot.get_updates(
  File "/home/bs/.virtualenvs/telegram/lib/python3.10/site-packages/telegram/ext/_extbot.py", line 524, in get_updates
    updates = await super().get_updates(
  File "/home/bs/.virtualenvs/telegram/lib/python3.10/site-packages/telegram/_bot.py", line 334, in decorator
    result = await func(*args, **kwargs)  # skipcq: PYL-E1102
  File "/home/bs/.virtualenvs/telegram/lib/python3.10/site-packages/telegram/_bot.py", line 3584, in get_updates
    await self._post(
  File "/home/bs/.virtualenvs/telegram/lib/python3.10/site-packages/telegram/_bot.py", line 422, in _post
    return await self._do_post(
  File "/home/bs/.virtualenvs/telegram/lib/python3.10/site-packages/telegram/ext/_extbot.py", line 306, in _do_post
    return await super()._do_post(
  File "/home/bs/.virtualenvs/telegram/lib/python3.10/site-packages/telegram/_bot.py", line 453, in _do_post
    return await request.post(
  File "/home/bs/.virtualenvs/telegram/lib/python3.10/site-packages/telegram/request/_baserequest.py", line 165, in post
    result = await self._request_wrapper(
  File "/home/bs/.virtualenvs/telegram/lib/python3.10/site-packages/telegram/request/_baserequest.py", line 332, in _request_wrapper
    raise NetworkError(description or "Bad Gateway")
telegram.error.NetworkError: Bad Gateway
Error while getting Updates: Bad Gateway
No error handlers are registered, logging exception.
Traceback (most recent call last):
  File "/home/bs/.virtualenvs/telegram/lib/python3.10/site-packages/telegram/ext/_updater.py", line 600, in _network_loop_retry
    if not await action_cb():
  File "/home/bs/.virtualenvs/telegram/lib/python3.10/site-packages/telegram/ext/_updater.py", line 327, in polling_action_cb
    raise exc
  File "/home/bs/.virtualenvs/telegram/lib/python3.10/site-packages/telegram/ext/_updater.py", line 312, in polling_action_cb
    updates = await self.bot.get_updates(
  File "/home/bs/.virtualenvs/telegram/lib/python3.10/site-packages/telegram/ext/_extbot.py", line 524, in get_updates
    updates = await super().get_updates(
  File "/home/bs/.virtualenvs/telegram/lib/python3.10/site-packages/telegram/_bot.py", line 334, in decorator
    result = await func(*args, **kwargs)  # skipcq: PYL-E1102
  File "/home/bs/.virtualenvs/telegram/lib/python3.10/site-packages/telegram/_bot.py", line 3584, in get_updates
    await self._post(
  File "/home/bs/.virtualenvs/telegram/lib/python3.10/site-packages/telegram/_bot.py", line 422, in _post
    return await self._do_post(
  File "/home/bs/.virtualenvs/telegram/lib/python3.10/site-packages/telegram/ext/_extbot.py", line 306, in _do_post
    return await super()._do_post(
  File "/home/bs/.virtualenvs/telegram/lib/python3.10/site-packages/telegram/_bot.py", line 453, in _do_post
    return await request.post(
  File "/home/bs/.virtualenvs/telegram/lib/python3.10/site-packages/telegram/request/_baserequest.py", line 165, in post
    result = await self._request_wrapper(
  File "/home/bs/.virtualenvs/telegram/lib/python3.10/site-packages/telegram/request/_baserequest.py", line 332, in _request_wrapper
    raise NetworkError(description or "Bad Gateway")
telegram.error.NetworkError: Bad Gateway
Error while getting Updates: Bad Gateway
No error handlers are registered, logging exception.
Traceback (most recent call last):
  File "/home/bs/.virtualenvs/telegram/lib/python3.10/site-packages/telegram/ext/_updater.py", line 600, in _network_loop_retry
    if not await action_cb():
  File "/home/bs/.virtualenvs/telegram/lib/python3.10/site-packages/telegram/ext/_updater.py", line 327, in polling_action_cb
    raise exc
  File "/home/bs/.virtualenvs/telegram/lib/python3.10/site-packages/telegram/ext/_updater.py", line 312, in polling_action_cb
    updates = await self.bot.get_updates(
  File "/home/bs/.virtualenvs/telegram/lib/python3.10/site-packages/telegram/ext/_extbot.py", line 524, in get_updates
    updates = await super().get_updates(
  File "/home/bs/.virtualenvs/telegram/lib/python3.10/site-packages/telegram/_bot.py", line 334, in decorator
    result = await func(*args, **kwargs)  # skipcq: PYL-E1102
  File "/home/bs/.virtualenvs/telegram/lib/python3.10/site-packages/telegram/_bot.py", line 3584, in get_updates
    await self._post(
  File "/home/bs/.virtualenvs/telegram/lib/python3.10/site-packages/telegram/_bot.py", line 422, in _post
    return await self._do_post(
  File "/home/bs/.virtualenvs/telegram/lib/python3.10/site-packages/telegram/ext/_extbot.py", line 306, in _do_post
    return await super()._do_post(
  File "/home/bs/.virtualenvs/telegram/lib/python3.10/site-packages/telegram/_bot.py", line 453, in _do_post
    return await request.post(
  File "/home/bs/.virtualenvs/telegram/lib/python3.10/site-packages/telegram/request/_baserequest.py", line 165, in post
    result = await self._request_wrapper(
  File "/home/bs/.virtualenvs/telegram/lib/python3.10/site-packages/telegram/request/_baserequest.py", line 332, in _request_wrapper
    raise NetworkError(description or "Bad Gateway")
telegram.error.NetworkError: Bad Gateway
Error while getting Updates: httpx HTTPError: 
No error handlers are registered, logging exception.
Traceback (most recent call last):
  File "/usr/lib/python3.10/asyncio/selector_events.py", line 854, in _read_ready__data_received
    data = self._sock.recv(self.max_size)
ConnectionResetError: [Errno 104] Connection reset by peer

The above exception was the direct cause of the following exception:

Traceback (most recent call last):
  File "/home/bs/.virtualenvs/telegram/lib/python3.10/site-packages/httpcore/_exceptions.py", line 10, in map_exceptions
    yield
  File "/home/bs/.virtualenvs/telegram/lib/python3.10/site-packages/httpcore/backends/asyncio.py", line 34, in read
    return await self._stream.receive(max_bytes=max_bytes)
  File "/home/bs/.virtualenvs/telegram/lib/python3.10/site-packages/anyio/streams/tls.py", line 195, in receive
    data = await self._call_sslobject_method(self._ssl_object.read, max_bytes)
  File "/home/bs/.virtualenvs/telegram/lib/python3.10/site-packages/anyio/streams/tls.py", line 137, in _call_sslobject_method
    data = await self.transport_stream.receive()
  File "/home/bs/.virtualenvs/telegram/lib/python3.10/site-packages/anyio/_backends/_asyncio.py", line 1274, in receive
    raise self._protocol.exception
anyio.BrokenResourceError

During handling of the above exception, another exception occurred:

Traceback (most recent call last):
  File "/home/bs/.virtualenvs/telegram/lib/python3.10/site-packages/httpx/_transports/default.py", line 60, in map_httpcore_exceptions
    yield
  File "/home/bs/.virtualenvs/telegram/lib/python3.10/site-packages/httpx/_transports/default.py", line 353, in handle_async_request
    resp = await self._pool.handle_async_request(req)
  File "/home/bs/.virtualenvs/telegram/lib/python3.10/site-packages/httpcore/_async/connection_pool.py", line 253, in handle_async_request
    raise exc
  File "/home/bs/.virtualenvs/telegram/lib/python3.10/site-packages/httpcore/_async/connection_pool.py", line 237, in handle_async_request
    response = await connection.handle_async_request(request)
  File "/home/bs/.virtualenvs/telegram/lib/python3.10/site-packages/httpcore/_async/connection.py", line 90, in handle_async_request
    return await self._connection.handle_async_request(request)
  File "/home/bs/.virtualenvs/telegram/lib/python3.10/site-packages/httpcore/_async/http11.py", line 112, in handle_async_request
    raise exc
  File "/home/bs/.virtualenvs/telegram/lib/python3.10/site-packages/httpcore/_async/http11.py", line 91, in handle_async_request
    ) = await self._receive_response_headers(**kwargs)
  File "/home/bs/.virtualenvs/telegram/lib/python3.10/site-packages/httpcore/_async/http11.py", line 155, in _receive_response_headers
    event = await self._receive_event(timeout=timeout)
  File "/home/bs/.virtualenvs/telegram/lib/python3.10/site-packages/httpcore/_async/http11.py", line 191, in _receive_event
    data = await self._network_stream.read(
  File "/home/bs/.virtualenvs/telegram/lib/python3.10/site-packages/httpcore/backends/asyncio.py", line 31, in read
    with map_exceptions(exc_map):
  File "/usr/lib/python3.10/contextlib.py", line 153, in __exit__
    self.gen.throw(typ, value, traceback)
  File "/home/bs/.virtualenvs/telegram/lib/python3.10/site-packages/httpcore/_exceptions.py", line 14, in map_exceptions
    raise to_exc(exc)
httpcore.ReadError

The above exception was the direct cause of the following exception:

Traceback (most recent call last):
  File "/home/bs/.virtualenvs/telegram/lib/python3.10/site-packages/telegram/request/_httpxrequest.py", line 183, in do_request
    res = await self._client.request(
  File "/home/bs/.virtualenvs/telegram/lib/python3.10/site-packages/httpx/_client.py", line 1533, in request
    return await self.send(request, auth=auth, follow_redirects=follow_redirects)
  File "/home/bs/.virtualenvs/telegram/lib/python3.10/site-packages/httpx/_client.py", line 1620, in send
    response = await self._send_handling_auth(
  File "/home/bs/.virtualenvs/telegram/lib/python3.10/site-packages/httpx/_client.py", line 1648, in _send_handling_auth
    response = await self._send_handling_redirects(
  File "/home/bs/.virtualenvs/telegram/lib/python3.10/site-packages/httpx/_client.py", line 1685, in _send_handling_redirects
    response = await self._send_single_request(request)
  File "/home/bs/.virtualenvs/telegram/lib/python3.10/site-packages/httpx/_client.py", line 1722, in _send_single_request
    response = await transport.handle_async_request(request)
  File "/home/bs/.virtualenvs/telegram/lib/python3.10/site-packages/httpx/_transports/default.py", line 352, in handle_async_request
    with map_httpcore_exceptions():
  File "/usr/lib/python3.10/contextlib.py", line 153, in __exit__
    self.gen.throw(typ, value, traceback)
  File "/home/bs/.virtualenvs/telegram/lib/python3.10/site-packages/httpx/_transports/default.py", line 77, in map_httpcore_exceptions
    raise mapped_exc(message) from exc
httpx.ReadError

The above exception was the direct cause of the following exception:

Traceback (most recent call last):
  File "/home/bs/.virtualenvs/telegram/lib/python3.10/site-packages/telegram/ext/_updater.py", line 600, in _network_loop_retry
    if not await action_cb():
  File "/home/bs/.virtualenvs/telegram/lib/python3.10/site-packages/telegram/ext/_updater.py", line 327, in polling_action_cb
    raise exc
  File "/home/bs/.virtualenvs/telegram/lib/python3.10/site-packages/telegram/ext/_updater.py", line 312, in polling_action_cb
    updates = await self.bot.get_updates(
  File "/home/bs/.virtualenvs/telegram/lib/python3.10/site-packages/telegram/ext/_extbot.py", line 524, in get_updates
    updates = await super().get_updates(
  File "/home/bs/.virtualenvs/telegram/lib/python3.10/site-packages/telegram/_bot.py", line 334, in decorator
    result = await func(*args, **kwargs)  # skipcq: PYL-E1102
  File "/home/bs/.virtualenvs/telegram/lib/python3.10/site-packages/telegram/_bot.py", line 3584, in get_updates
    await self._post(
  File "/home/bs/.virtualenvs/telegram/lib/python3.10/site-packages/telegram/_bot.py", line 422, in _post
    return await self._do_post(
  File "/home/bs/.virtualenvs/telegram/lib/python3.10/site-packages/telegram/ext/_extbot.py", line 306, in _do_post
    return await super()._do_post(
  File "/home/bs/.virtualenvs/telegram/lib/python3.10/site-packages/telegram/_bot.py", line 453, in _do_post
    return await request.post(
  File "/home/bs/.virtualenvs/telegram/lib/python3.10/site-packages/telegram/request/_baserequest.py", line 165, in post
    result = await self._request_wrapper(
  File "/home/bs/.virtualenvs/telegram/lib/python3.10/site-packages/telegram/request/_baserequest.py", line 288, in _request_wrapper
    raise exc
  File "/home/bs/.virtualenvs/telegram/lib/python3.10/site-packages/telegram/request/_baserequest.py", line 274, in _request_wrapper
    code, payload = await self.do_request(
  File "/home/bs/.virtualenvs/telegram/lib/python3.10/site-packages/telegram/request/_httpxrequest.py", line 204, in do_request
    raise NetworkError(f"httpx HTTPError: {err}") from err
telegram.error.NetworkError: httpx HTTPError: 
/home/bs/python-scripts/telegram-bot/bot.py:66: RuntimeWarning: coroutine 'Message.reply_text' was never awaited
  update.message.reply_text("You have to reply to a message for me to translate",
RuntimeWarning: Enable tracemalloc to get the object allocation traceback
/home/bs/python-scripts/telegram-bot/bot.py:66: RuntimeWarning: coroutine 'Message.reply_text' was never awaited
  update.message.reply_text("You have to reply to a message for me to translate",
RuntimeWarning: Enable tracemalloc to get the object allocation traceback
/home/bs/.virtualenvs/telegram/lib/python3.10/site-packages/pydub/utils.py:198: RuntimeWarning: Couldn't find ffprobe or avprobe - defaulting to ffprobe, but may not work
  warn("Couldn't find ffprobe or avprobe - defaulting to ffprobe, but may not work", RuntimeWarning)
No error handlers are registered, logging exception.
Traceback (most recent call last):
  File "/home/bs/.virtualenvs/telegram/lib/python3.10/site-packages/telegram/ext/_application.py", line 1063, in process_update
    await coroutine
  File "/home/bs/.virtualenvs/telegram/lib/python3.10/site-packages/telegram/ext/_handler.py", line 141, in handle_update
    return await self.callback(update, context)
  File "/home/bs/python-scripts/telegram-bot/bot.py", line 36, in send_esperanto
    AudioSegment.from_mp3(f.name).export("word_audio.ogg", format="ogg")
  File "/home/bs/.virtualenvs/telegram/lib/python3.10/site-packages/pydub/audio_segment.py", line 796, in from_mp3
    return cls.from_file(file, 'mp3', parameters=parameters)
  File "/home/bs/.virtualenvs/telegram/lib/python3.10/site-packages/pydub/audio_segment.py", line 728, in from_file
    info = mediainfo_json(orig_file, read_ahead_limit=read_ahead_limit)
  File "/home/bs/.virtualenvs/telegram/lib/python3.10/site-packages/pydub/utils.py", line 274, in mediainfo_json
    res = Popen(command, stdin=stdin_parameter, stdout=PIPE, stderr=PIPE)
  File "/usr/lib/python3.10/subprocess.py", line 969, in __init__
    self._execute_child(args, executable, preexec_fn, close_fds,
  File "/usr/lib/python3.10/subprocess.py", line 1845, in _execute_child
    raise child_exception_type(errno_num, err_msg, err_filename)
FileNotFoundError: [Errno 2] No such file or directory: 'ffprobe'
/home/bs/.virtualenvs/telegram/lib/python3.10/site-packages/pydub/utils.py:198: RuntimeWarning: Couldn't find ffprobe or avprobe - defaulting to ffprobe, but may not work
  warn("Couldn't find ffprobe or avprobe - defaulting to ffprobe, but may not work", RuntimeWarning)
No error handlers are registered, logging exception.
Traceback (most recent call last):
  File "/home/bs/.virtualenvs/telegram/lib/python3.10/site-packages/telegram/ext/_application.py", line 1063, in process_update
    await coroutine
  File "/home/bs/.virtualenvs/telegram/lib/python3.10/site-packages/telegram/ext/_handler.py", line 141, in handle_update
    return await self.callback(update, context)
  File "/home/bs/python-scripts/telegram-bot/bot.py", line 36, in send_esperanto
    AudioSegment.from_mp3(f.name).export("word_audio.ogg", format="ogg")
  File "/home/bs/.virtualenvs/telegram/lib/python3.10/site-packages/pydub/audio_segment.py", line 796, in from_mp3
    return cls.from_file(file, 'mp3', parameters=parameters)
  File "/home/bs/.virtualenvs/telegram/lib/python3.10/site-packages/pydub/audio_segment.py", line 728, in from_file
    info = mediainfo_json(orig_file, read_ahead_limit=read_ahead_limit)
  File "/home/bs/.virtualenvs/telegram/lib/python3.10/site-packages/pydub/utils.py", line 274, in mediainfo_json
    res = Popen(command, stdin=stdin_parameter, stdout=PIPE, stderr=PIPE)
  File "/usr/lib/python3.10/subprocess.py", line 969, in __init__
    self._execute_child(args, executable, preexec_fn, close_fds,
  File "/usr/lib/python3.10/subprocess.py", line 1845, in _execute_child
    raise child_exception_type(errno_num, err_msg, err_filename)
FileNotFoundError: [Errno 2] No such file or directory: 'ffprobe'
Error while getting Updates: Bad Gateway
No error handlers are registered, logging exception.
Traceback (most recent call last):
  File "/home/bs/.virtualenvs/telegram/lib/python3.10/site-packages/telegram/ext/_updater.py", line 600, in _network_loop_retry
    if not await action_cb():
  File "/home/bs/.virtualenvs/telegram/lib/python3.10/site-packages/telegram/ext/_updater.py", line 327, in polling_action_cb
    raise exc
  File "/home/bs/.virtualenvs/telegram/lib/python3.10/site-packages/telegram/ext/_updater.py", line 312, in polling_action_cb
    updates = await self.bot.get_updates(
  File "/home/bs/.virtualenvs/telegram/lib/python3.10/site-packages/telegram/ext/_extbot.py", line 524, in get_updates
    updates = await super().get_updates(
  File "/home/bs/.virtualenvs/telegram/lib/python3.10/site-packages/telegram/_bot.py", line 334, in decorator
    result = await func(*args, **kwargs)  # skipcq: PYL-E1102
  File "/home/bs/.virtualenvs/telegram/lib/python3.10/site-packages/telegram/_bot.py", line 3584, in get_updates
    await self._post(
  File "/home/bs/.virtualenvs/telegram/lib/python3.10/site-packages/telegram/_bot.py", line 422, in _post
    return await self._do_post(
  File "/home/bs/.virtualenvs/telegram/lib/python3.10/site-packages/telegram/ext/_extbot.py", line 306, in _do_post
    return await super()._do_post(
  File "/home/bs/.virtualenvs/telegram/lib/python3.10/site-packages/telegram/_bot.py", line 453, in _do_post
    return await request.post(
  File "/home/bs/.virtualenvs/telegram/lib/python3.10/site-packages/telegram/request/_baserequest.py", line 165, in post
    result = await self._request_wrapper(
  File "/home/bs/.virtualenvs/telegram/lib/python3.10/site-packages/telegram/request/_baserequest.py", line 332, in _request_wrapper
    raise NetworkError(description or "Bad Gateway")
telegram.error.NetworkError: Bad Gateway
No error handlers are registered, logging exception.
Traceback (most recent call last):
  File "/home/bs/.virtualenvs/telegram/lib/python3.10/site-packages/telegram/ext/_application.py", line 1063, in process_update
    await coroutine
  File "/home/bs/.virtualenvs/telegram/lib/python3.10/site-packages/telegram/ext/_handler.py", line 141, in handle_update
    return await self.callback(update, context)
  File "/home/bs/python-scripts/telegram-bot/bot.py", line 64, in send_translate
    replied_to = update.message.reply_to_message
AttributeError: 'NoneType' object has no attribute 'reply_to_message'
Error while getting Updates: Bad Gateway
No error handlers are registered, logging exception.
Traceback (most recent call last):
  File "/home/bs/.virtualenvs/telegram/lib/python3.10/site-packages/telegram/ext/_updater.py", line 600, in _network_loop_retry
    if not await action_cb():
  File "/home/bs/.virtualenvs/telegram/lib/python3.10/site-packages/telegram/ext/_updater.py", line 327, in polling_action_cb
    raise exc
  File "/home/bs/.virtualenvs/telegram/lib/python3.10/site-packages/telegram/ext/_updater.py", line 312, in polling_action_cb
    updates = await self.bot.get_updates(
  File "/home/bs/.virtualenvs/telegram/lib/python3.10/site-packages/telegram/ext/_extbot.py", line 524, in get_updates
    updates = await super().get_updates(
  File "/home/bs/.virtualenvs/telegram/lib/python3.10/site-packages/telegram/_bot.py", line 334, in decorator
    result = await func(*args, **kwargs)  # skipcq: PYL-E1102
  File "/home/bs/.virtualenvs/telegram/lib/python3.10/site-packages/telegram/_bot.py", line 3584, in get_updates
    await self._post(
  File "/home/bs/.virtualenvs/telegram/lib/python3.10/site-packages/telegram/_bot.py", line 422, in _post
    return await self._do_post(
  File "/home/bs/.virtualenvs/telegram/lib/python3.10/site-packages/telegram/ext/_extbot.py", line 306, in _do_post
    return await super()._do_post(
  File "/home/bs/.virtualenvs/telegram/lib/python3.10/site-packages/telegram/_bot.py", line 453, in _do_post
    return await request.post(
  File "/home/bs/.virtualenvs/telegram/lib/python3.10/site-packages/telegram/request/_baserequest.py", line 165, in post
    result = await self._request_wrapper(
  File "/home/bs/.virtualenvs/telegram/lib/python3.10/site-packages/telegram/request/_baserequest.py", line 332, in _request_wrapper
    raise NetworkError(description or "Bad Gateway")
telegram.error.NetworkError: Bad Gateway
Error while getting Updates: Bad Gateway
No error handlers are registered, logging exception.
Traceback (most recent call last):
  File "/home/bs/.virtualenvs/telegram/lib/python3.10/site-packages/telegram/ext/_updater.py", line 600, in _network_loop_retry
    if not await action_cb():
  File "/home/bs/.virtualenvs/telegram/lib/python3.10/site-packages/telegram/ext/_updater.py", line 327, in polling_action_cb
    raise exc
  File "/home/bs/.virtualenvs/telegram/lib/python3.10/site-packages/telegram/ext/_updater.py", line 312, in polling_action_cb
    updates = await self.bot.get_updates(
  File "/home/bs/.virtualenvs/telegram/lib/python3.10/site-packages/telegram/ext/_extbot.py", line 524, in get_updates
    updates = await super().get_updates(
  File "/home/bs/.virtualenvs/telegram/lib/python3.10/site-packages/telegram/_bot.py", line 334, in decorator
    result = await func(*args, **kwargs)  # skipcq: PYL-E1102
  File "/home/bs/.virtualenvs/telegram/lib/python3.10/site-packages/telegram/_bot.py", line 3584, in get_updates
    await self._post(
  File "/home/bs/.virtualenvs/telegram/lib/python3.10/site-packages/telegram/_bot.py", line 422, in _post
    return await self._do_post(
  File "/home/bs/.virtualenvs/telegram/lib/python3.10/site-packages/telegram/ext/_extbot.py", line 306, in _do_post
    return await super()._do_post(
  File "/home/bs/.virtualenvs/telegram/lib/python3.10/site-packages/telegram/_bot.py", line 453, in _do_post
    return await request.post(
  File "/home/bs/.virtualenvs/telegram/lib/python3.10/site-packages/telegram/request/_baserequest.py", line 165, in post
    result = await self._request_wrapper(
  File "/home/bs/.virtualenvs/telegram/lib/python3.10/site-packages/telegram/request/_baserequest.py", line 332, in _request_wrapper
    raise NetworkError(description or "Bad Gateway")
telegram.error.NetworkError: Bad Gateway
Error while getting Updates: Bad Gateway
No error handlers are registered, logging exception.
Traceback (most recent call last):
  File "/home/bs/.virtualenvs/telegram/lib/python3.10/site-packages/telegram/ext/_updater.py", line 600, in _network_loop_retry
    if not await action_cb():
  File "/home/bs/.virtualenvs/telegram/lib/python3.10/site-packages/telegram/ext/_updater.py", line 327, in polling_action_cb
    raise exc
  File "/home/bs/.virtualenvs/telegram/lib/python3.10/site-packages/telegram/ext/_updater.py", line 312, in polling_action_cb
    updates = await self.bot.get_updates(
  File "/home/bs/.virtualenvs/telegram/lib/python3.10/site-packages/telegram/ext/_extbot.py", line 524, in get_updates
    updates = await super().get_updates(
  File "/home/bs/.virtualenvs/telegram/lib/python3.10/site-packages/telegram/_bot.py", line 334, in decorator
    result = await func(*args, **kwargs)  # skipcq: PYL-E1102
  File "/home/bs/.virtualenvs/telegram/lib/python3.10/site-packages/telegram/_bot.py", line 3584, in get_updates
    await self._post(
  File "/home/bs/.virtualenvs/telegram/lib/python3.10/site-packages/telegram/_bot.py", line 422, in _post
    return await self._do_post(
  File "/home/bs/.virtualenvs/telegram/lib/python3.10/site-packages/telegram/ext/_extbot.py", line 306, in _do_post
    return await super()._do_post(
  File "/home/bs/.virtualenvs/telegram/lib/python3.10/site-packages/telegram/_bot.py", line 453, in _do_post
    return await request.post(
  File "/home/bs/.virtualenvs/telegram/lib/python3.10/site-packages/telegram/request/_baserequest.py", line 165, in post
    result = await self._request_wrapper(
  File "/home/bs/.virtualenvs/telegram/lib/python3.10/site-packages/telegram/request/_baserequest.py", line 332, in _request_wrapper
    raise NetworkError(description or "Bad Gateway")
telegram.error.NetworkError: Bad Gateway
Error while getting Updates: httpx HTTPError: All connection attempts failed
No error handlers are registered, logging exception.
anyio._backends._asyncio.ExceptionGroup: 2 exceptions were raised in the task group:
----------------------------
Traceback (most recent call last):
  File "/home/bs/.virtualenvs/telegram/lib/python3.10/site-packages/anyio/_core/_sockets.py", line 164, in try_connect
    stream = await asynclib.connect_tcp(remote_host, remote_port, local_address)
  File "/home/bs/.virtualenvs/telegram/lib/python3.10/site-packages/anyio/_backends/_asyncio.py", line 1691, in connect_tcp
    await get_running_loop().create_connection(
  File "/usr/lib/python3.10/asyncio/base_events.py", line 1064, in create_connection
    raise exceptions[0]
  File "/usr/lib/python3.10/asyncio/base_events.py", line 1049, in create_connection
    sock = await self._connect_sock(
  File "/usr/lib/python3.10/asyncio/base_events.py", line 960, in _connect_sock
    await self.sock_connect(sock, address)
  File "/usr/lib/python3.10/asyncio/selector_events.py", line 500, in sock_connect
    return await fut
  File "/usr/lib/python3.10/asyncio/selector_events.py", line 505, in _sock_connect
    sock.connect(address)
OSError: [Errno 101] Network is unreachable
----------------------------
Traceback (most recent call last):
  File "/home/bs/.virtualenvs/telegram/lib/python3.10/site-packages/anyio/_core/_sockets.py", line 164, in try_connect
    stream = await asynclib.connect_tcp(remote_host, remote_port, local_address)
  File "/home/bs/.virtualenvs/telegram/lib/python3.10/site-packages/anyio/_backends/_asyncio.py", line 1691, in connect_tcp
    await get_running_loop().create_connection(
  File "/usr/lib/python3.10/asyncio/base_events.py", line 1064, in create_connection
    raise exceptions[0]
  File "/usr/lib/python3.10/asyncio/base_events.py", line 1049, in create_connection
    sock = await self._connect_sock(
  File "/usr/lib/python3.10/asyncio/base_events.py", line 960, in _connect_sock
    await self.sock_connect(sock, address)
  File "/usr/lib/python3.10/asyncio/selector_events.py", line 500, in sock_connect
    return await fut
  File "/usr/lib/python3.10/asyncio/selector_events.py", line 535, in _sock_connect_cb
    raise OSError(err, f'Connect call failed {address}')
OSError: [Errno 113] Connect call failed ('149.154.167.220', 443)


The above exception was the direct cause of the following exception:

Traceback (most recent call last):
  File "/home/bs/.virtualenvs/telegram/lib/python3.10/site-packages/httpcore/_exceptions.py", line 10, in map_exceptions
    yield
  File "/home/bs/.virtualenvs/telegram/lib/python3.10/site-packages/httpcore/backends/asyncio.py", line 111, in connect_tcp
    stream: anyio.abc.ByteStream = await anyio.connect_tcp(
  File "/home/bs/.virtualenvs/telegram/lib/python3.10/site-packages/anyio/_core/_sockets.py", line 222, in connect_tcp
    raise OSError("All connection attempts failed") from cause
OSError: All connection attempts failed

During handling of the above exception, another exception occurred:

Traceback (most recent call last):
  File "/home/bs/.virtualenvs/telegram/lib/python3.10/site-packages/httpx/_transports/default.py", line 60, in map_httpcore_exceptions
    yield
  File "/home/bs/.virtualenvs/telegram/lib/python3.10/site-packages/httpx/_transports/default.py", line 353, in handle_async_request
    resp = await self._pool.handle_async_request(req)
  File "/home/bs/.virtualenvs/telegram/lib/python3.10/site-packages/httpcore/_async/connection_pool.py", line 253, in handle_async_request
    raise exc
  File "/home/bs/.virtualenvs/telegram/lib/python3.10/site-packages/httpcore/_async/connection_pool.py", line 237, in handle_async_request
    response = await connection.handle_async_request(request)
  File "/home/bs/.virtualenvs/telegram/lib/python3.10/site-packages/httpcore/_async/connection.py", line 86, in handle_async_request
    raise exc
  File "/home/bs/.virtualenvs/telegram/lib/python3.10/site-packages/httpcore/_async/connection.py", line 63, in handle_async_request
    stream = await self._connect(request)
  File "/home/bs/.virtualenvs/telegram/lib/python3.10/site-packages/httpcore/_async/connection.py", line 111, in _connect
    stream = await self._network_backend.connect_tcp(**kwargs)
  File "/home/bs/.virtualenvs/telegram/lib/python3.10/site-packages/httpcore/backends/auto.py", line 29, in connect_tcp
    return await self._backend.connect_tcp(
  File "/home/bs/.virtualenvs/telegram/lib/python3.10/site-packages/httpcore/backends/asyncio.py", line 109, in connect_tcp
    with map_exceptions(exc_map):
  File "/usr/lib/python3.10/contextlib.py", line 153, in __exit__
    self.gen.throw(typ, value, traceback)
  File "/home/bs/.virtualenvs/telegram/lib/python3.10/site-packages/httpcore/_exceptions.py", line 14, in map_exceptions
    raise to_exc(exc)
httpcore.ConnectError: All connection attempts failed

The above exception was the direct cause of the following exception:

Traceback (most recent call last):
  File "/home/bs/.virtualenvs/telegram/lib/python3.10/site-packages/telegram/request/_httpxrequest.py", line 183, in do_request
    res = await self._client.request(
  File "/home/bs/.virtualenvs/telegram/lib/python3.10/site-packages/httpx/_client.py", line 1533, in request
    return await self.send(request, auth=auth, follow_redirects=follow_redirects)
  File "/home/bs/.virtualenvs/telegram/lib/python3.10/site-packages/httpx/_client.py", line 1620, in send
    response = await self._send_handling_auth(
  File "/home/bs/.virtualenvs/telegram/lib/python3.10/site-packages/httpx/_client.py", line 1648, in _send_handling_auth
    response = await self._send_handling_redirects(
  File "/home/bs/.virtualenvs/telegram/lib/python3.10/site-packages/httpx/_client.py", line 1685, in _send_handling_redirects
    response = await self._send_single_request(request)
  File "/home/bs/.virtualenvs/telegram/lib/python3.10/site-packages/httpx/_client.py", line 1722, in _send_single_request
    response = await transport.handle_async_request(request)
  File "/home/bs/.virtualenvs/telegram/lib/python3.10/site-packages/httpx/_transports/default.py", line 352, in handle_async_request
    with map_httpcore_exceptions():
  File "/usr/lib/python3.10/contextlib.py", line 153, in __exit__
    self.gen.throw(typ, value, traceback)
  File "/home/bs/.virtualenvs/telegram/lib/python3.10/site-packages/httpx/_transports/default.py", line 77, in map_httpcore_exceptions
    raise mapped_exc(message) from exc
httpx.ConnectError: All connection attempts failed

The above exception was the direct cause of the following exception:

Traceback (most recent call last):
  File "/home/bs/.virtualenvs/telegram/lib/python3.10/site-packages/telegram/ext/_updater.py", line 600, in _network_loop_retry
    if not await action_cb():
  File "/home/bs/.virtualenvs/telegram/lib/python3.10/site-packages/telegram/ext/_updater.py", line 327, in polling_action_cb
    raise exc
  File "/home/bs/.virtualenvs/telegram/lib/python3.10/site-packages/telegram/ext/_updater.py", line 312, in polling_action_cb
    updates = await self.bot.get_updates(
  File "/home/bs/.virtualenvs/telegram/lib/python3.10/site-packages/telegram/ext/_extbot.py", line 524, in get_updates
    updates = await super().get_updates(
  File "/home/bs/.virtualenvs/telegram/lib/python3.10/site-packages/telegram/_bot.py", line 334, in decorator
    result = await func(*args, **kwargs)  # skipcq: PYL-E1102
  File "/home/bs/.virtualenvs/telegram/lib/python3.10/site-packages/telegram/_bot.py", line 3584, in get_updates
    await self._post(
  File "/home/bs/.virtualenvs/telegram/lib/python3.10/site-packages/telegram/_bot.py", line 422, in _post
    return await self._do_post(
  File "/home/bs/.virtualenvs/telegram/lib/python3.10/site-packages/telegram/ext/_extbot.py", line 306, in _do_post
    return await super()._do_post(
  File "/home/bs/.virtualenvs/telegram/lib/python3.10/site-packages/telegram/_bot.py", line 453, in _do_post
    return await request.post(
  File "/home/bs/.virtualenvs/telegram/lib/python3.10/site-packages/telegram/request/_baserequest.py", line 165, in post
    result = await self._request_wrapper(
  File "/home/bs/.virtualenvs/telegram/lib/python3.10/site-packages/telegram/request/_baserequest.py", line 288, in _request_wrapper
    raise exc
  File "/home/bs/.virtualenvs/telegram/lib/python3.10/site-packages/telegram/request/_baserequest.py", line 274, in _request_wrapper
    code, payload = await self.do_request(
  File "/home/bs/.virtualenvs/telegram/lib/python3.10/site-packages/telegram/request/_httpxrequest.py", line 204, in do_request
    raise NetworkError(f"httpx HTTPError: {err}") from err
telegram.error.NetworkError: httpx HTTPError: All connection attempts failed
Error while getting Updates: httpx HTTPError: All connection attempts failed
No error handlers are registered, logging exception.
anyio._backends._asyncio.ExceptionGroup: 2 exceptions were raised in the task group:
----------------------------
Traceback (most recent call last):
  File "/home/bs/.virtualenvs/telegram/lib/python3.10/site-packages/anyio/_core/_sockets.py", line 164, in try_connect
    stream = await asynclib.connect_tcp(remote_host, remote_port, local_address)
  File "/home/bs/.virtualenvs/telegram/lib/python3.10/site-packages/anyio/_backends/_asyncio.py", line 1691, in connect_tcp
    await get_running_loop().create_connection(
  File "/usr/lib/python3.10/asyncio/base_events.py", line 1064, in create_connection
    raise exceptions[0]
  File "/usr/lib/python3.10/asyncio/base_events.py", line 1049, in create_connection
    sock = await self._connect_sock(
  File "/usr/lib/python3.10/asyncio/base_events.py", line 960, in _connect_sock
    await self.sock_connect(sock, address)
  File "/usr/lib/python3.10/asyncio/selector_events.py", line 500, in sock_connect
    return await fut
  File "/usr/lib/python3.10/asyncio/selector_events.py", line 505, in _sock_connect
    sock.connect(address)
OSError: [Errno 101] Network is unreachable
----------------------------
Traceback (most recent call last):
  File "/home/bs/.virtualenvs/telegram/lib/python3.10/site-packages/anyio/_core/_sockets.py", line 164, in try_connect
    stream = await asynclib.connect_tcp(remote_host, remote_port, local_address)
  File "/home/bs/.virtualenvs/telegram/lib/python3.10/site-packages/anyio/_backends/_asyncio.py", line 1691, in connect_tcp
    await get_running_loop().create_connection(
  File "/usr/lib/python3.10/asyncio/base_events.py", line 1064, in create_connection
    raise exceptions[0]
  File "/usr/lib/python3.10/asyncio/base_events.py", line 1049, in create_connection
    sock = await self._connect_sock(
  File "/usr/lib/python3.10/asyncio/base_events.py", line 960, in _connect_sock
    await self.sock_connect(sock, address)
  File "/usr/lib/python3.10/asyncio/selector_events.py", line 500, in sock_connect
    return await fut
  File "/usr/lib/python3.10/asyncio/selector_events.py", line 535, in _sock_connect_cb
    raise OSError(err, f'Connect call failed {address}')
OSError: [Errno 113] Connect call failed ('149.154.167.220', 443)


The above exception was the direct cause of the following exception:

Traceback (most recent call last):
  File "/home/bs/.virtualenvs/telegram/lib/python3.10/site-packages/httpcore/_exceptions.py", line 10, in map_exceptions
    yield
  File "/home/bs/.virtualenvs/telegram/lib/python3.10/site-packages/httpcore/backends/asyncio.py", line 111, in connect_tcp
    stream: anyio.abc.ByteStream = await anyio.connect_tcp(
  File "/home/bs/.virtualenvs/telegram/lib/python3.10/site-packages/anyio/_core/_sockets.py", line 222, in connect_tcp
    raise OSError("All connection attempts failed") from cause
OSError: All connection attempts failed

During handling of the above exception, another exception occurred:

Traceback (most recent call last):
  File "/home/bs/.virtualenvs/telegram/lib/python3.10/site-packages/httpx/_transports/default.py", line 60, in map_httpcore_exceptions
    yield
  File "/home/bs/.virtualenvs/telegram/lib/python3.10/site-packages/httpx/_transports/default.py", line 353, in handle_async_request
    resp = await self._pool.handle_async_request(req)
  File "/home/bs/.virtualenvs/telegram/lib/python3.10/site-packages/httpcore/_async/connection_pool.py", line 253, in handle_async_request
    raise exc
  File "/home/bs/.virtualenvs/telegram/lib/python3.10/site-packages/httpcore/_async/connection_pool.py", line 237, in handle_async_request
    response = await connection.handle_async_request(request)
  File "/home/bs/.virtualenvs/telegram/lib/python3.10/site-packages/httpcore/_async/connection.py", line 86, in handle_async_request
    raise exc
  File "/home/bs/.virtualenvs/telegram/lib/python3.10/site-packages/httpcore/_async/connection.py", line 63, in handle_async_request
    stream = await self._connect(request)
  File "/home/bs/.virtualenvs/telegram/lib/python3.10/site-packages/httpcore/_async/connection.py", line 111, in _connect
    stream = await self._network_backend.connect_tcp(**kwargs)
  File "/home/bs/.virtualenvs/telegram/lib/python3.10/site-packages/httpcore/backends/auto.py", line 29, in connect_tcp
    return await self._backend.connect_tcp(
  File "/home/bs/.virtualenvs/telegram/lib/python3.10/site-packages/httpcore/backends/asyncio.py", line 109, in connect_tcp
    with map_exceptions(exc_map):
  File "/usr/lib/python3.10/contextlib.py", line 153, in __exit__
    self.gen.throw(typ, value, traceback)
  File "/home/bs/.virtualenvs/telegram/lib/python3.10/site-packages/httpcore/_exceptions.py", line 14, in map_exceptions
    raise to_exc(exc)
httpcore.ConnectError: All connection attempts failed

The above exception was the direct cause of the following exception:

Traceback (most recent call last):
  File "/home/bs/.virtualenvs/telegram/lib/python3.10/site-packages/telegram/request/_httpxrequest.py", line 183, in do_request
    res = await self._client.request(
  File "/home/bs/.virtualenvs/telegram/lib/python3.10/site-packages/httpx/_client.py", line 1533, in request
    return await self.send(request, auth=auth, follow_redirects=follow_redirects)
  File "/home/bs/.virtualenvs/telegram/lib/python3.10/site-packages/httpx/_client.py", line 1620, in send
    response = await self._send_handling_auth(
  File "/home/bs/.virtualenvs/telegram/lib/python3.10/site-packages/httpx/_client.py", line 1648, in _send_handling_auth
    response = await self._send_handling_redirects(
  File "/home/bs/.virtualenvs/telegram/lib/python3.10/site-packages/httpx/_client.py", line 1685, in _send_handling_redirects
    response = await self._send_single_request(request)
  File "/home/bs/.virtualenvs/telegram/lib/python3.10/site-packages/httpx/_client.py", line 1722, in _send_single_request
    response = await transport.handle_async_request(request)
  File "/home/bs/.virtualenvs/telegram/lib/python3.10/site-packages/httpx/_transports/default.py", line 352, in handle_async_request
    with map_httpcore_exceptions():
  File "/usr/lib/python3.10/contextlib.py", line 153, in __exit__
    self.gen.throw(typ, value, traceback)
  File "/home/bs/.virtualenvs/telegram/lib/python3.10/site-packages/httpx/_transports/default.py", line 77, in map_httpcore_exceptions
    raise mapped_exc(message) from exc
httpx.ConnectError: All connection attempts failed

The above exception was the direct cause of the following exception:

Traceback (most recent call last):
  File "/home/bs/.virtualenvs/telegram/lib/python3.10/site-packages/telegram/ext/_updater.py", line 600, in _network_loop_retry
    if not await action_cb():
  File "/home/bs/.virtualenvs/telegram/lib/python3.10/site-packages/telegram/ext/_updater.py", line 327, in polling_action_cb
    raise exc
  File "/home/bs/.virtualenvs/telegram/lib/python3.10/site-packages/telegram/ext/_updater.py", line 312, in polling_action_cb
    updates = await self.bot.get_updates(
  File "/home/bs/.virtualenvs/telegram/lib/python3.10/site-packages/telegram/ext/_extbot.py", line 524, in get_updates
    updates = await super().get_updates(
  File "/home/bs/.virtualenvs/telegram/lib/python3.10/site-packages/telegram/_bot.py", line 334, in decorator
    result = await func(*args, **kwargs)  # skipcq: PYL-E1102
  File "/home/bs/.virtualenvs/telegram/lib/python3.10/site-packages/telegram/_bot.py", line 3584, in get_updates
    await self._post(
  File "/home/bs/.virtualenvs/telegram/lib/python3.10/site-packages/telegram/_bot.py", line 422, in _post
    return await self._do_post(
  File "/home/bs/.virtualenvs/telegram/lib/python3.10/site-packages/telegram/ext/_extbot.py", line 306, in _do_post
    return await super()._do_post(
  File "/home/bs/.virtualenvs/telegram/lib/python3.10/site-packages/telegram/_bot.py", line 453, in _do_post
    return await request.post(
  File "/home/bs/.virtualenvs/telegram/lib/python3.10/site-packages/telegram/request/_baserequest.py", line 165, in post
    result = await self._request_wrapper(
  File "/home/bs/.virtualenvs/telegram/lib/python3.10/site-packages/telegram/request/_baserequest.py", line 288, in _request_wrapper
    raise exc
  File "/home/bs/.virtualenvs/telegram/lib/python3.10/site-packages/telegram/request/_baserequest.py", line 274, in _request_wrapper
    code, payload = await self.do_request(
  File "/home/bs/.virtualenvs/telegram/lib/python3.10/site-packages/telegram/request/_httpxrequest.py", line 204, in do_request
    raise NetworkError(f"httpx HTTPError: {err}") from err
telegram.error.NetworkError: httpx HTTPError: All connection attempts failed
Error while getting Updates: httpx HTTPError: All connection attempts failed
No error handlers are registered, logging exception.
anyio._backends._asyncio.ExceptionGroup: 2 exceptions were raised in the task group:
----------------------------
Traceback (most recent call last):
  File "/home/bs/.virtualenvs/telegram/lib/python3.10/site-packages/anyio/_core/_sockets.py", line 164, in try_connect
    stream = await asynclib.connect_tcp(remote_host, remote_port, local_address)
  File "/home/bs/.virtualenvs/telegram/lib/python3.10/site-packages/anyio/_backends/_asyncio.py", line 1691, in connect_tcp
    await get_running_loop().create_connection(
  File "/usr/lib/python3.10/asyncio/base_events.py", line 1064, in create_connection
    raise exceptions[0]
  File "/usr/lib/python3.10/asyncio/base_events.py", line 1049, in create_connection
    sock = await self._connect_sock(
  File "/usr/lib/python3.10/asyncio/base_events.py", line 960, in _connect_sock
    await self.sock_connect(sock, address)
  File "/usr/lib/python3.10/asyncio/selector_events.py", line 500, in sock_connect
    return await fut
  File "/usr/lib/python3.10/asyncio/selector_events.py", line 505, in _sock_connect
    sock.connect(address)
OSError: [Errno 101] Network is unreachable
----------------------------
Traceback (most recent call last):
  File "/home/bs/.virtualenvs/telegram/lib/python3.10/site-packages/anyio/_core/_sockets.py", line 164, in try_connect
    stream = await asynclib.connect_tcp(remote_host, remote_port, local_address)
  File "/home/bs/.virtualenvs/telegram/lib/python3.10/site-packages/anyio/_backends/_asyncio.py", line 1691, in connect_tcp
    await get_running_loop().create_connection(
  File "/usr/lib/python3.10/asyncio/base_events.py", line 1064, in create_connection
    raise exceptions[0]
  File "/usr/lib/python3.10/asyncio/base_events.py", line 1049, in create_connection
    sock = await self._connect_sock(
  File "/usr/lib/python3.10/asyncio/base_events.py", line 960, in _connect_sock
    await self.sock_connect(sock, address)
  File "/usr/lib/python3.10/asyncio/selector_events.py", line 500, in sock_connect
    return await fut
  File "/usr/lib/python3.10/asyncio/selector_events.py", line 535, in _sock_connect_cb
    raise OSError(err, f'Connect call failed {address}')
OSError: [Errno 113] Connect call failed ('149.154.167.220', 443)


The above exception was the direct cause of the following exception:

Traceback (most recent call last):
  File "/home/bs/.virtualenvs/telegram/lib/python3.10/site-packages/httpcore/_exceptions.py", line 10, in map_exceptions
    yield
  File "/home/bs/.virtualenvs/telegram/lib/python3.10/site-packages/httpcore/backends/asyncio.py", line 111, in connect_tcp
    stream: anyio.abc.ByteStream = await anyio.connect_tcp(
  File "/home/bs/.virtualenvs/telegram/lib/python3.10/site-packages/anyio/_core/_sockets.py", line 222, in connect_tcp
    raise OSError("All connection attempts failed") from cause
OSError: All connection attempts failed

During handling of the above exception, another exception occurred:

Traceback (most recent call last):
  File "/home/bs/.virtualenvs/telegram/lib/python3.10/site-packages/httpx/_transports/default.py", line 60, in map_httpcore_exceptions
    yield
  File "/home/bs/.virtualenvs/telegram/lib/python3.10/site-packages/httpx/_transports/default.py", line 353, in handle_async_request
    resp = await self._pool.handle_async_request(req)
  File "/home/bs/.virtualenvs/telegram/lib/python3.10/site-packages/httpcore/_async/connection_pool.py", line 253, in handle_async_request
    raise exc
  File "/home/bs/.virtualenvs/telegram/lib/python3.10/site-packages/httpcore/_async/connection_pool.py", line 237, in handle_async_request
    response = await connection.handle_async_request(request)
  File "/home/bs/.virtualenvs/telegram/lib/python3.10/site-packages/httpcore/_async/connection.py", line 86, in handle_async_request
    raise exc
  File "/home/bs/.virtualenvs/telegram/lib/python3.10/site-packages/httpcore/_async/connection.py", line 63, in handle_async_request
    stream = await self._connect(request)
  File "/home/bs/.virtualenvs/telegram/lib/python3.10/site-packages/httpcore/_async/connection.py", line 111, in _connect
    stream = await self._network_backend.connect_tcp(**kwargs)
  File "/home/bs/.virtualenvs/telegram/lib/python3.10/site-packages/httpcore/backends/auto.py", line 29, in connect_tcp
    return await self._backend.connect_tcp(
  File "/home/bs/.virtualenvs/telegram/lib/python3.10/site-packages/httpcore/backends/asyncio.py", line 109, in connect_tcp
    with map_exceptions(exc_map):
  File "/usr/lib/python3.10/contextlib.py", line 153, in __exit__
    self.gen.throw(typ, value, traceback)
  File "/home/bs/.virtualenvs/telegram/lib/python3.10/site-packages/httpcore/_exceptions.py", line 14, in map_exceptions
    raise to_exc(exc)
httpcore.ConnectError: All connection attempts failed

The above exception was the direct cause of the following exception:

Traceback (most recent call last):
  File "/home/bs/.virtualenvs/telegram/lib/python3.10/site-packages/telegram/request/_httpxrequest.py", line 183, in do_request
    res = await self._client.request(
  File "/home/bs/.virtualenvs/telegram/lib/python3.10/site-packages/httpx/_client.py", line 1533, in request
    return await self.send(request, auth=auth, follow_redirects=follow_redirects)
  File "/home/bs/.virtualenvs/telegram/lib/python3.10/site-packages/httpx/_client.py", line 1620, in send
    response = await self._send_handling_auth(
  File "/home/bs/.virtualenvs/telegram/lib/python3.10/site-packages/httpx/_client.py", line 1648, in _send_handling_auth
    response = await self._send_handling_redirects(
  File "/home/bs/.virtualenvs/telegram/lib/python3.10/site-packages/httpx/_client.py", line 1685, in _send_handling_redirects
    response = await self._send_single_request(request)
  File "/home/bs/.virtualenvs/telegram/lib/python3.10/site-packages/httpx/_client.py", line 1722, in _send_single_request
    response = await transport.handle_async_request(request)
  File "/home/bs/.virtualenvs/telegram/lib/python3.10/site-packages/httpx/_transports/default.py", line 352, in handle_async_request
    with map_httpcore_exceptions():
  File "/usr/lib/python3.10/contextlib.py", line 153, in __exit__
    self.gen.throw(typ, value, traceback)
  File "/home/bs/.virtualenvs/telegram/lib/python3.10/site-packages/httpx/_transports/default.py", line 77, in map_httpcore_exceptions
    raise mapped_exc(message) from exc
httpx.ConnectError: All connection attempts failed

The above exception was the direct cause of the following exception:

Traceback (most recent call last):
  File "/home/bs/.virtualenvs/telegram/lib/python3.10/site-packages/telegram/ext/_updater.py", line 600, in _network_loop_retry
    if not await action_cb():
  File "/home/bs/.virtualenvs/telegram/lib/python3.10/site-packages/telegram/ext/_updater.py", line 327, in polling_action_cb
    raise exc
  File "/home/bs/.virtualenvs/telegram/lib/python3.10/site-packages/telegram/ext/_updater.py", line 312, in polling_action_cb
    updates = await self.bot.get_updates(
  File "/home/bs/.virtualenvs/telegram/lib/python3.10/site-packages/telegram/ext/_extbot.py", line 524, in get_updates
    updates = await super().get_updates(
  File "/home/bs/.virtualenvs/telegram/lib/python3.10/site-packages/telegram/_bot.py", line 334, in decorator
    result = await func(*args, **kwargs)  # skipcq: PYL-E1102
  File "/home/bs/.virtualenvs/telegram/lib/python3.10/site-packages/telegram/_bot.py", line 3584, in get_updates
    await self._post(
  File "/home/bs/.virtualenvs/telegram/lib/python3.10/site-packages/telegram/_bot.py", line 422, in _post
    return await self._do_post(
  File "/home/bs/.virtualenvs/telegram/lib/python3.10/site-packages/telegram/ext/_extbot.py", line 306, in _do_post
    return await super()._do_post(
  File "/home/bs/.virtualenvs/telegram/lib/python3.10/site-packages/telegram/_bot.py", line 453, in _do_post
    return await request.post(
  File "/home/bs/.virtualenvs/telegram/lib/python3.10/site-packages/telegram/request/_baserequest.py", line 165, in post
    result = await self._request_wrapper(
  File "/home/bs/.virtualenvs/telegram/lib/python3.10/site-packages/telegram/request/_baserequest.py", line 288, in _request_wrapper
    raise exc
  File "/home/bs/.virtualenvs/telegram/lib/python3.10/site-packages/telegram/request/_baserequest.py", line 274, in _request_wrapper
    code, payload = await self.do_request(
  File "/home/bs/.virtualenvs/telegram/lib/python3.10/site-packages/telegram/request/_httpxrequest.py", line 204, in do_request
    raise NetworkError(f"httpx HTTPError: {err}") from err
telegram.error.NetworkError: httpx HTTPError: All connection attempts failed
Error while getting Updates: httpx HTTPError: All connection attempts failed
No error handlers are registered, logging exception.
anyio._backends._asyncio.ExceptionGroup: 2 exceptions were raised in the task group:
----------------------------
Traceback (most recent call last):
  File "/home/bs/.virtualenvs/telegram/lib/python3.10/site-packages/anyio/_core/_sockets.py", line 164, in try_connect
    stream = await asynclib.connect_tcp(remote_host, remote_port, local_address)
  File "/home/bs/.virtualenvs/telegram/lib/python3.10/site-packages/anyio/_backends/_asyncio.py", line 1691, in connect_tcp
    await get_running_loop().create_connection(
  File "/usr/lib/python3.10/asyncio/base_events.py", line 1064, in create_connection
    raise exceptions[0]
  File "/usr/lib/python3.10/asyncio/base_events.py", line 1049, in create_connection
    sock = await self._connect_sock(
  File "/usr/lib/python3.10/asyncio/base_events.py", line 960, in _connect_sock
    await self.sock_connect(sock, address)
  File "/usr/lib/python3.10/asyncio/selector_events.py", line 500, in sock_connect
    return await fut
  File "/usr/lib/python3.10/asyncio/selector_events.py", line 505, in _sock_connect
    sock.connect(address)
OSError: [Errno 101] Network is unreachable
----------------------------
Traceback (most recent call last):
  File "/home/bs/.virtualenvs/telegram/lib/python3.10/site-packages/anyio/_core/_sockets.py", line 164, in try_connect
    stream = await asynclib.connect_tcp(remote_host, remote_port, local_address)
  File "/home/bs/.virtualenvs/telegram/lib/python3.10/site-packages/anyio/_backends/_asyncio.py", line 1691, in connect_tcp
    await get_running_loop().create_connection(
  File "/usr/lib/python3.10/asyncio/base_events.py", line 1064, in create_connection
    raise exceptions[0]
  File "/usr/lib/python3.10/asyncio/base_events.py", line 1049, in create_connection
    sock = await self._connect_sock(
  File "/usr/lib/python3.10/asyncio/base_events.py", line 960, in _connect_sock
    await self.sock_connect(sock, address)
  File "/usr/lib/python3.10/asyncio/selector_events.py", line 500, in sock_connect
    return await fut
  File "/usr/lib/python3.10/asyncio/selector_events.py", line 535, in _sock_connect_cb
    raise OSError(err, f'Connect call failed {address}')
OSError: [Errno 113] Connect call failed ('149.154.167.220', 443)


The above exception was the direct cause of the following exception:

Traceback (most recent call last):
  File "/home/bs/.virtualenvs/telegram/lib/python3.10/site-packages/httpcore/_exceptions.py", line 10, in map_exceptions
    yield
  File "/home/bs/.virtualenvs/telegram/lib/python3.10/site-packages/httpcore/backends/asyncio.py", line 111, in connect_tcp
    stream: anyio.abc.ByteStream = await anyio.connect_tcp(
  File "/home/bs/.virtualenvs/telegram/lib/python3.10/site-packages/anyio/_core/_sockets.py", line 222, in connect_tcp
    raise OSError("All connection attempts failed") from cause
OSError: All connection attempts failed

During handling of the above exception, another exception occurred:

Traceback (most recent call last):
  File "/home/bs/.virtualenvs/telegram/lib/python3.10/site-packages/httpx/_transports/default.py", line 60, in map_httpcore_exceptions
    yield
  File "/home/bs/.virtualenvs/telegram/lib/python3.10/site-packages/httpx/_transports/default.py", line 353, in handle_async_request
    resp = await self._pool.handle_async_request(req)
  File "/home/bs/.virtualenvs/telegram/lib/python3.10/site-packages/httpcore/_async/connection_pool.py", line 253, in handle_async_request
    raise exc
  File "/home/bs/.virtualenvs/telegram/lib/python3.10/site-packages/httpcore/_async/connection_pool.py", line 237, in handle_async_request
    response = await connection.handle_async_request(request)
  File "/home/bs/.virtualenvs/telegram/lib/python3.10/site-packages/httpcore/_async/connection.py", line 86, in handle_async_request
    raise exc
  File "/home/bs/.virtualenvs/telegram/lib/python3.10/site-packages/httpcore/_async/connection.py", line 63, in handle_async_request
    stream = await self._connect(request)
  File "/home/bs/.virtualenvs/telegram/lib/python3.10/site-packages/httpcore/_async/connection.py", line 111, in _connect
    stream = await self._network_backend.connect_tcp(**kwargs)
  File "/home/bs/.virtualenvs/telegram/lib/python3.10/site-packages/httpcore/backends/auto.py", line 29, in connect_tcp
    return await self._backend.connect_tcp(
  File "/home/bs/.virtualenvs/telegram/lib/python3.10/site-packages/httpcore/backends/asyncio.py", line 109, in connect_tcp
    with map_exceptions(exc_map):
  File "/usr/lib/python3.10/contextlib.py", line 153, in __exit__
    self.gen.throw(typ, value, traceback)
  File "/home/bs/.virtualenvs/telegram/lib/python3.10/site-packages/httpcore/_exceptions.py", line 14, in map_exceptions
    raise to_exc(exc)
httpcore.ConnectError: All connection attempts failed

The above exception was the direct cause of the following exception:

Traceback (most recent call last):
  File "/home/bs/.virtualenvs/telegram/lib/python3.10/site-packages/telegram/request/_httpxrequest.py", line 183, in do_request
    res = await self._client.request(
  File "/home/bs/.virtualenvs/telegram/lib/python3.10/site-packages/httpx/_client.py", line 1533, in request
    return await self.send(request, auth=auth, follow_redirects=follow_redirects)
  File "/home/bs/.virtualenvs/telegram/lib/python3.10/site-packages/httpx/_client.py", line 1620, in send
    response = await self._send_handling_auth(
  File "/home/bs/.virtualenvs/telegram/lib/python3.10/site-packages/httpx/_client.py", line 1648, in _send_handling_auth
    response = await self._send_handling_redirects(
  File "/home/bs/.virtualenvs/telegram/lib/python3.10/site-packages/httpx/_client.py", line 1685, in _send_handling_redirects
    response = await self._send_single_request(request)
  File "/home/bs/.virtualenvs/telegram/lib/python3.10/site-packages/httpx/_client.py", line 1722, in _send_single_request
    response = await transport.handle_async_request(request)
  File "/home/bs/.virtualenvs/telegram/lib/python3.10/site-packages/httpx/_transports/default.py", line 352, in handle_async_request
    with map_httpcore_exceptions():
  File "/usr/lib/python3.10/contextlib.py", line 153, in __exit__
    self.gen.throw(typ, value, traceback)
  File "/home/bs/.virtualenvs/telegram/lib/python3.10/site-packages/httpx/_transports/default.py", line 77, in map_httpcore_exceptions
    raise mapped_exc(message) from exc
httpx.ConnectError: All connection attempts failed

The above exception was the direct cause of the following exception:

Traceback (most recent call last):
  File "/home/bs/.virtualenvs/telegram/lib/python3.10/site-packages/telegram/ext/_updater.py", line 600, in _network_loop_retry
    if not await action_cb():
  File "/home/bs/.virtualenvs/telegram/lib/python3.10/site-packages/telegram/ext/_updater.py", line 327, in polling_action_cb
    raise exc
  File "/home/bs/.virtualenvs/telegram/lib/python3.10/site-packages/telegram/ext/_updater.py", line 312, in polling_action_cb
    updates = await self.bot.get_updates(
  File "/home/bs/.virtualenvs/telegram/lib/python3.10/site-packages/telegram/ext/_extbot.py", line 524, in get_updates
    updates = await super().get_updates(
  File "/home/bs/.virtualenvs/telegram/lib/python3.10/site-packages/telegram/_bot.py", line 334, in decorator
    result = await func(*args, **kwargs)  # skipcq: PYL-E1102
  File "/home/bs/.virtualenvs/telegram/lib/python3.10/site-packages/telegram/_bot.py", line 3584, in get_updates
    await self._post(
  File "/home/bs/.virtualenvs/telegram/lib/python3.10/site-packages/telegram/_bot.py", line 422, in _post
    return await self._do_post(
  File "/home/bs/.virtualenvs/telegram/lib/python3.10/site-packages/telegram/ext/_extbot.py", line 306, in _do_post
    return await super()._do_post(
  File "/home/bs/.virtualenvs/telegram/lib/python3.10/site-packages/telegram/_bot.py", line 453, in _do_post
    return await request.post(
  File "/home/bs/.virtualenvs/telegram/lib/python3.10/site-packages/telegram/request/_baserequest.py", line 165, in post
    result = await self._request_wrapper(
  File "/home/bs/.virtualenvs/telegram/lib/python3.10/site-packages/telegram/request/_baserequest.py", line 288, in _request_wrapper
    raise exc
  File "/home/bs/.virtualenvs/telegram/lib/python3.10/site-packages/telegram/request/_baserequest.py", line 274, in _request_wrapper
    code, payload = await self.do_request(
  File "/home/bs/.virtualenvs/telegram/lib/python3.10/site-packages/telegram/request/_httpxrequest.py", line 204, in do_request
    raise NetworkError(f"httpx HTTPError: {err}") from err
telegram.error.NetworkError: httpx HTTPError: All connection attempts failed
Error while getting Updates: httpx HTTPError: All connection attempts failed
No error handlers are registered, logging exception.
anyio._backends._asyncio.ExceptionGroup: 2 exceptions were raised in the task group:
----------------------------
Traceback (most recent call last):
  File "/home/bs/.virtualenvs/telegram/lib/python3.10/site-packages/anyio/_core/_sockets.py", line 164, in try_connect
    stream = await asynclib.connect_tcp(remote_host, remote_port, local_address)
  File "/home/bs/.virtualenvs/telegram/lib/python3.10/site-packages/anyio/_backends/_asyncio.py", line 1691, in connect_tcp
    await get_running_loop().create_connection(
  File "/usr/lib/python3.10/asyncio/base_events.py", line 1064, in create_connection
    raise exceptions[0]
  File "/usr/lib/python3.10/asyncio/base_events.py", line 1049, in create_connection
    sock = await self._connect_sock(
  File "/usr/lib/python3.10/asyncio/base_events.py", line 960, in _connect_sock
    await self.sock_connect(sock, address)
  File "/usr/lib/python3.10/asyncio/selector_events.py", line 500, in sock_connect
    return await fut
  File "/usr/lib/python3.10/asyncio/selector_events.py", line 505, in _sock_connect
    sock.connect(address)
OSError: [Errno 101] Network is unreachable
----------------------------
Traceback (most recent call last):
  File "/home/bs/.virtualenvs/telegram/lib/python3.10/site-packages/anyio/_core/_sockets.py", line 164, in try_connect
    stream = await asynclib.connect_tcp(remote_host, remote_port, local_address)
  File "/home/bs/.virtualenvs/telegram/lib/python3.10/site-packages/anyio/_backends/_asyncio.py", line 1691, in connect_tcp
    await get_running_loop().create_connection(
  File "/usr/lib/python3.10/asyncio/base_events.py", line 1064, in create_connection
    raise exceptions[0]
  File "/usr/lib/python3.10/asyncio/base_events.py", line 1049, in create_connection
    sock = await self._connect_sock(
  File "/usr/lib/python3.10/asyncio/base_events.py", line 960, in _connect_sock
    await self.sock_connect(sock, address)
  File "/usr/lib/python3.10/asyncio/selector_events.py", line 500, in sock_connect
    return await fut
  File "/usr/lib/python3.10/asyncio/selector_events.py", line 535, in _sock_connect_cb
    raise OSError(err, f'Connect call failed {address}')
OSError: [Errno 113] Connect call failed ('149.154.167.220', 443)


The above exception was the direct cause of the following exception:

Traceback (most recent call last):
  File "/home/bs/.virtualenvs/telegram/lib/python3.10/site-packages/httpcore/_exceptions.py", line 10, in map_exceptions
    yield
  File "/home/bs/.virtualenvs/telegram/lib/python3.10/site-packages/httpcore/backends/asyncio.py", line 111, in connect_tcp
    stream: anyio.abc.ByteStream = await anyio.connect_tcp(
  File "/home/bs/.virtualenvs/telegram/lib/python3.10/site-packages/anyio/_core/_sockets.py", line 222, in connect_tcp
    raise OSError("All connection attempts failed") from cause
OSError: All connection attempts failed

During handling of the above exception, another exception occurred:

Traceback (most recent call last):
  File "/home/bs/.virtualenvs/telegram/lib/python3.10/site-packages/httpx/_transports/default.py", line 60, in map_httpcore_exceptions
    yield
  File "/home/bs/.virtualenvs/telegram/lib/python3.10/site-packages/httpx/_transports/default.py", line 353, in handle_async_request
    resp = await self._pool.handle_async_request(req)
  File "/home/bs/.virtualenvs/telegram/lib/python3.10/site-packages/httpcore/_async/connection_pool.py", line 253, in handle_async_request
    raise exc
  File "/home/bs/.virtualenvs/telegram/lib/python3.10/site-packages/httpcore/_async/connection_pool.py", line 237, in handle_async_request
    response = await connection.handle_async_request(request)
  File "/home/bs/.virtualenvs/telegram/lib/python3.10/site-packages/httpcore/_async/connection.py", line 86, in handle_async_request
    raise exc
  File "/home/bs/.virtualenvs/telegram/lib/python3.10/site-packages/httpcore/_async/connection.py", line 63, in handle_async_request
    stream = await self._connect(request)
  File "/home/bs/.virtualenvs/telegram/lib/python3.10/site-packages/httpcore/_async/connection.py", line 111, in _connect
    stream = await self._network_backend.connect_tcp(**kwargs)
  File "/home/bs/.virtualenvs/telegram/lib/python3.10/site-packages/httpcore/backends/auto.py", line 29, in connect_tcp
    return await self._backend.connect_tcp(
  File "/home/bs/.virtualenvs/telegram/lib/python3.10/site-packages/httpcore/backends/asyncio.py", line 109, in connect_tcp
    with map_exceptions(exc_map):
  File "/usr/lib/python3.10/contextlib.py", line 153, in __exit__
    self.gen.throw(typ, value, traceback)
  File "/home/bs/.virtualenvs/telegram/lib/python3.10/site-packages/httpcore/_exceptions.py", line 14, in map_exceptions
    raise to_exc(exc)
httpcore.ConnectError: All connection attempts failed

The above exception was the direct cause of the following exception:

Traceback (most recent call last):
  File "/home/bs/.virtualenvs/telegram/lib/python3.10/site-packages/telegram/request/_httpxrequest.py", line 183, in do_request
    res = await self._client.request(
  File "/home/bs/.virtualenvs/telegram/lib/python3.10/site-packages/httpx/_client.py", line 1533, in request
    return await self.send(request, auth=auth, follow_redirects=follow_redirects)
  File "/home/bs/.virtualenvs/telegram/lib/python3.10/site-packages/httpx/_client.py", line 1620, in send
    response = await self._send_handling_auth(
  File "/home/bs/.virtualenvs/telegram/lib/python3.10/site-packages/httpx/_client.py", line 1648, in _send_handling_auth
    response = await self._send_handling_redirects(
  File "/home/bs/.virtualenvs/telegram/lib/python3.10/site-packages/httpx/_client.py", line 1685, in _send_handling_redirects
    response = await self._send_single_request(request)
  File "/home/bs/.virtualenvs/telegram/lib/python3.10/site-packages/httpx/_client.py", line 1722, in _send_single_request
    response = await transport.handle_async_request(request)
  File "/home/bs/.virtualenvs/telegram/lib/python3.10/site-packages/httpx/_transports/default.py", line 352, in handle_async_request
    with map_httpcore_exceptions():
  File "/usr/lib/python3.10/contextlib.py", line 153, in __exit__
    self.gen.throw(typ, value, traceback)
  File "/home/bs/.virtualenvs/telegram/lib/python3.10/site-packages/httpx/_transports/default.py", line 77, in map_httpcore_exceptions
    raise mapped_exc(message) from exc
httpx.ConnectError: All connection attempts failed

The above exception was the direct cause of the following exception:

Traceback (most recent call last):
  File "/home/bs/.virtualenvs/telegram/lib/python3.10/site-packages/telegram/ext/_updater.py", line 600, in _network_loop_retry
    if not await action_cb():
  File "/home/bs/.virtualenvs/telegram/lib/python3.10/site-packages/telegram/ext/_updater.py", line 327, in polling_action_cb
    raise exc
  File "/home/bs/.virtualenvs/telegram/lib/python3.10/site-packages/telegram/ext/_updater.py", line 312, in polling_action_cb
    updates = await self.bot.get_updates(
  File "/home/bs/.virtualenvs/telegram/lib/python3.10/site-packages/telegram/ext/_extbot.py", line 524, in get_updates
    updates = await super().get_updates(
  File "/home/bs/.virtualenvs/telegram/lib/python3.10/site-packages/telegram/_bot.py", line 334, in decorator
    result = await func(*args, **kwargs)  # skipcq: PYL-E1102
  File "/home/bs/.virtualenvs/telegram/lib/python3.10/site-packages/telegram/_bot.py", line 3584, in get_updates
    await self._post(
  File "/home/bs/.virtualenvs/telegram/lib/python3.10/site-packages/telegram/_bot.py", line 422, in _post
    return await self._do_post(
  File "/home/bs/.virtualenvs/telegram/lib/python3.10/site-packages/telegram/ext/_extbot.py", line 306, in _do_post
    return await super()._do_post(
  File "/home/bs/.virtualenvs/telegram/lib/python3.10/site-packages/telegram/_bot.py", line 453, in _do_post
    return await request.post(
  File "/home/bs/.virtualenvs/telegram/lib/python3.10/site-packages/telegram/request/_baserequest.py", line 165, in post
    result = await self._request_wrapper(
  File "/home/bs/.virtualenvs/telegram/lib/python3.10/site-packages/telegram/request/_baserequest.py", line 288, in _request_wrapper
    raise exc
  File "/home/bs/.virtualenvs/telegram/lib/python3.10/site-packages/telegram/request/_baserequest.py", line 274, in _request_wrapper
    code, payload = await self.do_request(
  File "/home/bs/.virtualenvs/telegram/lib/python3.10/site-packages/telegram/request/_httpxrequest.py", line 204, in do_request
    raise NetworkError(f"httpx HTTPError: {err}") from err
telegram.error.NetworkError: httpx HTTPError: All connection attempts failed
Error while getting Updates: httpx HTTPError: All connection attempts failed
No error handlers are registered, logging exception.
anyio._backends._asyncio.ExceptionGroup: 2 exceptions were raised in the task group:
----------------------------
Traceback (most recent call last):
  File "/home/bs/.virtualenvs/telegram/lib/python3.10/site-packages/anyio/_core/_sockets.py", line 164, in try_connect
    stream = await asynclib.connect_tcp(remote_host, remote_port, local_address)
  File "/home/bs/.virtualenvs/telegram/lib/python3.10/site-packages/anyio/_backends/_asyncio.py", line 1691, in connect_tcp
    await get_running_loop().create_connection(
  File "/usr/lib/python3.10/asyncio/base_events.py", line 1064, in create_connection
    raise exceptions[0]
  File "/usr/lib/python3.10/asyncio/base_events.py", line 1049, in create_connection
    sock = await self._connect_sock(
  File "/usr/lib/python3.10/asyncio/base_events.py", line 960, in _connect_sock
    await self.sock_connect(sock, address)
  File "/usr/lib/python3.10/asyncio/selector_events.py", line 500, in sock_connect
    return await fut
  File "/usr/lib/python3.10/asyncio/selector_events.py", line 505, in _sock_connect
    sock.connect(address)
OSError: [Errno 101] Network is unreachable
----------------------------
Traceback (most recent call last):
  File "/home/bs/.virtualenvs/telegram/lib/python3.10/site-packages/anyio/_core/_sockets.py", line 164, in try_connect
    stream = await asynclib.connect_tcp(remote_host, remote_port, local_address)
  File "/home/bs/.virtualenvs/telegram/lib/python3.10/site-packages/anyio/_backends/_asyncio.py", line 1691, in connect_tcp
    await get_running_loop().create_connection(
  File "/usr/lib/python3.10/asyncio/base_events.py", line 1064, in create_connection
    raise exceptions[0]
  File "/usr/lib/python3.10/asyncio/base_events.py", line 1049, in create_connection
    sock = await self._connect_sock(
  File "/usr/lib/python3.10/asyncio/base_events.py", line 960, in _connect_sock
    await self.sock_connect(sock, address)
  File "/usr/lib/python3.10/asyncio/selector_events.py", line 500, in sock_connect
    return await fut
  File "/usr/lib/python3.10/asyncio/selector_events.py", line 535, in _sock_connect_cb
    raise OSError(err, f'Connect call failed {address}')
OSError: [Errno 113] Connect call failed ('149.154.167.220', 443)


The above exception was the direct cause of the following exception:

Traceback (most recent call last):
  File "/home/bs/.virtualenvs/telegram/lib/python3.10/site-packages/httpcore/_exceptions.py", line 10, in map_exceptions
    yield
  File "/home/bs/.virtualenvs/telegram/lib/python3.10/site-packages/httpcore/backends/asyncio.py", line 111, in connect_tcp
    stream: anyio.abc.ByteStream = await anyio.connect_tcp(
  File "/home/bs/.virtualenvs/telegram/lib/python3.10/site-packages/anyio/_core/_sockets.py", line 222, in connect_tcp
    raise OSError("All connection attempts failed") from cause
OSError: All connection attempts failed

During handling of the above exception, another exception occurred:

Traceback (most recent call last):
  File "/home/bs/.virtualenvs/telegram/lib/python3.10/site-packages/httpx/_transports/default.py", line 60, in map_httpcore_exceptions
    yield
  File "/home/bs/.virtualenvs/telegram/lib/python3.10/site-packages/httpx/_transports/default.py", line 353, in handle_async_request
    resp = await self._pool.handle_async_request(req)
  File "/home/bs/.virtualenvs/telegram/lib/python3.10/site-packages/httpcore/_async/connection_pool.py", line 253, in handle_async_request
    raise exc
  File "/home/bs/.virtualenvs/telegram/lib/python3.10/site-packages/httpcore/_async/connection_pool.py", line 237, in handle_async_request
    response = await connection.handle_async_request(request)
  File "/home/bs/.virtualenvs/telegram/lib/python3.10/site-packages/httpcore/_async/connection.py", line 86, in handle_async_request
    raise exc
  File "/home/bs/.virtualenvs/telegram/lib/python3.10/site-packages/httpcore/_async/connection.py", line 63, in handle_async_request
    stream = await self._connect(request)
  File "/home/bs/.virtualenvs/telegram/lib/python3.10/site-packages/httpcore/_async/connection.py", line 111, in _connect
    stream = await self._network_backend.connect_tcp(**kwargs)
  File "/home/bs/.virtualenvs/telegram/lib/python3.10/site-packages/httpcore/backends/auto.py", line 29, in connect_tcp
    return await self._backend.connect_tcp(
  File "/home/bs/.virtualenvs/telegram/lib/python3.10/site-packages/httpcore/backends/asyncio.py", line 109, in connect_tcp
    with map_exceptions(exc_map):
  File "/usr/lib/python3.10/contextlib.py", line 153, in __exit__
    self.gen.throw(typ, value, traceback)
  File "/home/bs/.virtualenvs/telegram/lib/python3.10/site-packages/httpcore/_exceptions.py", line 14, in map_exceptions
    raise to_exc(exc)
httpcore.ConnectError: All connection attempts failed

The above exception was the direct cause of the following exception:

Traceback (most recent call last):
  File "/home/bs/.virtualenvs/telegram/lib/python3.10/site-packages/telegram/request/_httpxrequest.py", line 183, in do_request
    res = await self._client.request(
  File "/home/bs/.virtualenvs/telegram/lib/python3.10/site-packages/httpx/_client.py", line 1533, in request
    return await self.send(request, auth=auth, follow_redirects=follow_redirects)
  File "/home/bs/.virtualenvs/telegram/lib/python3.10/site-packages/httpx/_client.py", line 1620, in send
    response = await self._send_handling_auth(
  File "/home/bs/.virtualenvs/telegram/lib/python3.10/site-packages/httpx/_client.py", line 1648, in _send_handling_auth
    response = await self._send_handling_redirects(
  File "/home/bs/.virtualenvs/telegram/lib/python3.10/site-packages/httpx/_client.py", line 1685, in _send_handling_redirects
    response = await self._send_single_request(request)
  File "/home/bs/.virtualenvs/telegram/lib/python3.10/site-packages/httpx/_client.py", line 1722, in _send_single_request
    response = await transport.handle_async_request(request)
  File "/home/bs/.virtualenvs/telegram/lib/python3.10/site-packages/httpx/_transports/default.py", line 352, in handle_async_request
    with map_httpcore_exceptions():
  File "/usr/lib/python3.10/contextlib.py", line 153, in __exit__
    self.gen.throw(typ, value, traceback)
  File "/home/bs/.virtualenvs/telegram/lib/python3.10/site-packages/httpx/_transports/default.py", line 77, in map_httpcore_exceptions
    raise mapped_exc(message) from exc
httpx.ConnectError: All connection attempts failed

The above exception was the direct cause of the following exception:

Traceback (most recent call last):
  File "/home/bs/.virtualenvs/telegram/lib/python3.10/site-packages/telegram/ext/_updater.py", line 600, in _network_loop_retry
    if not await action_cb():
  File "/home/bs/.virtualenvs/telegram/lib/python3.10/site-packages/telegram/ext/_updater.py", line 327, in polling_action_cb
    raise exc
  File "/home/bs/.virtualenvs/telegram/lib/python3.10/site-packages/telegram/ext/_updater.py", line 312, in polling_action_cb
    updates = await self.bot.get_updates(
  File "/home/bs/.virtualenvs/telegram/lib/python3.10/site-packages/telegram/ext/_extbot.py", line 524, in get_updates
    updates = await super().get_updates(
  File "/home/bs/.virtualenvs/telegram/lib/python3.10/site-packages/telegram/_bot.py", line 334, in decorator
    result = await func(*args, **kwargs)  # skipcq: PYL-E1102
  File "/home/bs/.virtualenvs/telegram/lib/python3.10/site-packages/telegram/_bot.py", line 3584, in get_updates
    await self._post(
  File "/home/bs/.virtualenvs/telegram/lib/python3.10/site-packages/telegram/_bot.py", line 422, in _post
    return await self._do_post(
  File "/home/bs/.virtualenvs/telegram/lib/python3.10/site-packages/telegram/ext/_extbot.py", line 306, in _do_post
    return await super()._do_post(
  File "/home/bs/.virtualenvs/telegram/lib/python3.10/site-packages/telegram/_bot.py", line 453, in _do_post
    return await request.post(
  File "/home/bs/.virtualenvs/telegram/lib/python3.10/site-packages/telegram/request/_baserequest.py", line 165, in post
    result = await self._request_wrapper(
  File "/home/bs/.virtualenvs/telegram/lib/python3.10/site-packages/telegram/request/_baserequest.py", line 288, in _request_wrapper
    raise exc
  File "/home/bs/.virtualenvs/telegram/lib/python3.10/site-packages/telegram/request/_baserequest.py", line 274, in _request_wrapper
    code, payload = await self.do_request(
  File "/home/bs/.virtualenvs/telegram/lib/python3.10/site-packages/telegram/request/_httpxrequest.py", line 204, in do_request
    raise NetworkError(f"httpx HTTPError: {err}") from err
telegram.error.NetworkError: httpx HTTPError: All connection attempts failed
Error while getting Updates: httpx HTTPError: All connection attempts failed
No error handlers are registered, logging exception.
anyio._backends._asyncio.ExceptionGroup: 2 exceptions were raised in the task group:
----------------------------
Traceback (most recent call last):
  File "/home/bs/.virtualenvs/telegram/lib/python3.10/site-packages/anyio/_core/_sockets.py", line 164, in try_connect
    stream = await asynclib.connect_tcp(remote_host, remote_port, local_address)
  File "/home/bs/.virtualenvs/telegram/lib/python3.10/site-packages/anyio/_backends/_asyncio.py", line 1691, in connect_tcp
    await get_running_loop().create_connection(
  File "/usr/lib/python3.10/asyncio/base_events.py", line 1064, in create_connection
    raise exceptions[0]
  File "/usr/lib/python3.10/asyncio/base_events.py", line 1049, in create_connection
    sock = await self._connect_sock(
  File "/usr/lib/python3.10/asyncio/base_events.py", line 960, in _connect_sock
    await self.sock_connect(sock, address)
  File "/usr/lib/python3.10/asyncio/selector_events.py", line 500, in sock_connect
    return await fut
  File "/usr/lib/python3.10/asyncio/selector_events.py", line 505, in _sock_connect
    sock.connect(address)
OSError: [Errno 101] Network is unreachable
----------------------------
Traceback (most recent call last):
  File "/home/bs/.virtualenvs/telegram/lib/python3.10/site-packages/anyio/_core/_sockets.py", line 164, in try_connect
    stream = await asynclib.connect_tcp(remote_host, remote_port, local_address)
  File "/home/bs/.virtualenvs/telegram/lib/python3.10/site-packages/anyio/_backends/_asyncio.py", line 1691, in connect_tcp
    await get_running_loop().create_connection(
  File "/usr/lib/python3.10/asyncio/base_events.py", line 1064, in create_connection
    raise exceptions[0]
  File "/usr/lib/python3.10/asyncio/base_events.py", line 1049, in create_connection
    sock = await self._connect_sock(
  File "/usr/lib/python3.10/asyncio/base_events.py", line 960, in _connect_sock
    await self.sock_connect(sock, address)
  File "/usr/lib/python3.10/asyncio/selector_events.py", line 500, in sock_connect
    return await fut
  File "/usr/lib/python3.10/asyncio/selector_events.py", line 535, in _sock_connect_cb
    raise OSError(err, f'Connect call failed {address}')
OSError: [Errno 113] Connect call failed ('149.154.167.220', 443)


The above exception was the direct cause of the following exception:

Traceback (most recent call last):
  File "/home/bs/.virtualenvs/telegram/lib/python3.10/site-packages/httpcore/_exceptions.py", line 10, in map_exceptions
    yield
  File "/home/bs/.virtualenvs/telegram/lib/python3.10/site-packages/httpcore/backends/asyncio.py", line 111, in connect_tcp
    stream: anyio.abc.ByteStream = await anyio.connect_tcp(
  File "/home/bs/.virtualenvs/telegram/lib/python3.10/site-packages/anyio/_core/_sockets.py", line 222, in connect_tcp
    raise OSError("All connection attempts failed") from cause
OSError: All connection attempts failed

During handling of the above exception, another exception occurred:

Traceback (most recent call last):
  File "/home/bs/.virtualenvs/telegram/lib/python3.10/site-packages/httpx/_transports/default.py", line 60, in map_httpcore_exceptions
    yield
  File "/home/bs/.virtualenvs/telegram/lib/python3.10/site-packages/httpx/_transports/default.py", line 353, in handle_async_request
    resp = await self._pool.handle_async_request(req)
  File "/home/bs/.virtualenvs/telegram/lib/python3.10/site-packages/httpcore/_async/connection_pool.py", line 253, in handle_async_request
    raise exc
  File "/home/bs/.virtualenvs/telegram/lib/python3.10/site-packages/httpcore/_async/connection_pool.py", line 237, in handle_async_request
    response = await connection.handle_async_request(request)
  File "/home/bs/.virtualenvs/telegram/lib/python3.10/site-packages/httpcore/_async/connection.py", line 86, in handle_async_request
    raise exc
  File "/home/bs/.virtualenvs/telegram/lib/python3.10/site-packages/httpcore/_async/connection.py", line 63, in handle_async_request
    stream = await self._connect(request)
  File "/home/bs/.virtualenvs/telegram/lib/python3.10/site-packages/httpcore/_async/connection.py", line 111, in _connect
    stream = await self._network_backend.connect_tcp(**kwargs)
  File "/home/bs/.virtualenvs/telegram/lib/python3.10/site-packages/httpcore/backends/auto.py", line 29, in connect_tcp
    return await self._backend.connect_tcp(
  File "/home/bs/.virtualenvs/telegram/lib/python3.10/site-packages/httpcore/backends/asyncio.py", line 109, in connect_tcp
    with map_exceptions(exc_map):
  File "/usr/lib/python3.10/contextlib.py", line 153, in __exit__
    self.gen.throw(typ, value, traceback)
  File "/home/bs/.virtualenvs/telegram/lib/python3.10/site-packages/httpcore/_exceptions.py", line 14, in map_exceptions
    raise to_exc(exc)
httpcore.ConnectError: All connection attempts failed

The above exception was the direct cause of the following exception:

Traceback (most recent call last):
  File "/home/bs/.virtualenvs/telegram/lib/python3.10/site-packages/telegram/request/_httpxrequest.py", line 183, in do_request
    res = await self._client.request(
  File "/home/bs/.virtualenvs/telegram/lib/python3.10/site-packages/httpx/_client.py", line 1533, in request
    return await self.send(request, auth=auth, follow_redirects=follow_redirects)
  File "/home/bs/.virtualenvs/telegram/lib/python3.10/site-packages/httpx/_client.py", line 1620, in send
    response = await self._send_handling_auth(
  File "/home/bs/.virtualenvs/telegram/lib/python3.10/site-packages/httpx/_client.py", line 1648, in _send_handling_auth
    response = await self._send_handling_redirects(
  File "/home/bs/.virtualenvs/telegram/lib/python3.10/site-packages/httpx/_client.py", line 1685, in _send_handling_redirects
    response = await self._send_single_request(request)
  File "/home/bs/.virtualenvs/telegram/lib/python3.10/site-packages/httpx/_client.py", line 1722, in _send_single_request
    response = await transport.handle_async_request(request)
  File "/home/bs/.virtualenvs/telegram/lib/python3.10/site-packages/httpx/_transports/default.py", line 352, in handle_async_request
    with map_httpcore_exceptions():
  File "/usr/lib/python3.10/contextlib.py", line 153, in __exit__
    self.gen.throw(typ, value, traceback)
  File "/home/bs/.virtualenvs/telegram/lib/python3.10/site-packages/httpx/_transports/default.py", line 77, in map_httpcore_exceptions
    raise mapped_exc(message) from exc
httpx.ConnectError: All connection attempts failed

The above exception was the direct cause of the following exception:

Traceback (most recent call last):
  File "/home/bs/.virtualenvs/telegram/lib/python3.10/site-packages/telegram/ext/_updater.py", line 600, in _network_loop_retry
    if not await action_cb():
  File "/home/bs/.virtualenvs/telegram/lib/python3.10/site-packages/telegram/ext/_updater.py", line 327, in polling_action_cb
    raise exc
  File "/home/bs/.virtualenvs/telegram/lib/python3.10/site-packages/telegram/ext/_updater.py", line 312, in polling_action_cb
    updates = await self.bot.get_updates(
  File "/home/bs/.virtualenvs/telegram/lib/python3.10/site-packages/telegram/ext/_extbot.py", line 524, in get_updates
    updates = await super().get_updates(
  File "/home/bs/.virtualenvs/telegram/lib/python3.10/site-packages/telegram/_bot.py", line 334, in decorator
    result = await func(*args, **kwargs)  # skipcq: PYL-E1102
  File "/home/bs/.virtualenvs/telegram/lib/python3.10/site-packages/telegram/_bot.py", line 3584, in get_updates
    await self._post(
  File "/home/bs/.virtualenvs/telegram/lib/python3.10/site-packages/telegram/_bot.py", line 422, in _post
    return await self._do_post(
  File "/home/bs/.virtualenvs/telegram/lib/python3.10/site-packages/telegram/ext/_extbot.py", line 306, in _do_post
    return await super()._do_post(
  File "/home/bs/.virtualenvs/telegram/lib/python3.10/site-packages/telegram/_bot.py", line 453, in _do_post
    return await request.post(
  File "/home/bs/.virtualenvs/telegram/lib/python3.10/site-packages/telegram/request/_baserequest.py", line 165, in post
    result = await self._request_wrapper(
  File "/home/bs/.virtualenvs/telegram/lib/python3.10/site-packages/telegram/request/_baserequest.py", line 288, in _request_wrapper
    raise exc
  File "/home/bs/.virtualenvs/telegram/lib/python3.10/site-packages/telegram/request/_baserequest.py", line 274, in _request_wrapper
    code, payload = await self.do_request(
  File "/home/bs/.virtualenvs/telegram/lib/python3.10/site-packages/telegram/request/_httpxrequest.py", line 204, in do_request
    raise NetworkError(f"httpx HTTPError: {err}") from err
telegram.error.NetworkError: httpx HTTPError: All connection attempts failed
Error while getting Updates: httpx HTTPError: All connection attempts failed
No error handlers are registered, logging exception.
anyio._backends._asyncio.ExceptionGroup: 2 exceptions were raised in the task group:
----------------------------
Traceback (most recent call last):
  File "/home/bs/.virtualenvs/telegram/lib/python3.10/site-packages/anyio/_core/_sockets.py", line 164, in try_connect
    stream = await asynclib.connect_tcp(remote_host, remote_port, local_address)
  File "/home/bs/.virtualenvs/telegram/lib/python3.10/site-packages/anyio/_backends/_asyncio.py", line 1691, in connect_tcp
    await get_running_loop().create_connection(
  File "/usr/lib/python3.10/asyncio/base_events.py", line 1064, in create_connection
    raise exceptions[0]
  File "/usr/lib/python3.10/asyncio/base_events.py", line 1049, in create_connection
    sock = await self._connect_sock(
  File "/usr/lib/python3.10/asyncio/base_events.py", line 960, in _connect_sock
    await self.sock_connect(sock, address)
  File "/usr/lib/python3.10/asyncio/selector_events.py", line 500, in sock_connect
    return await fut
  File "/usr/lib/python3.10/asyncio/selector_events.py", line 505, in _sock_connect
    sock.connect(address)
OSError: [Errno 101] Network is unreachable
----------------------------
Traceback (most recent call last):
  File "/home/bs/.virtualenvs/telegram/lib/python3.10/site-packages/anyio/_core/_sockets.py", line 164, in try_connect
    stream = await asynclib.connect_tcp(remote_host, remote_port, local_address)
  File "/home/bs/.virtualenvs/telegram/lib/python3.10/site-packages/anyio/_backends/_asyncio.py", line 1691, in connect_tcp
    await get_running_loop().create_connection(
  File "/usr/lib/python3.10/asyncio/base_events.py", line 1064, in create_connection
    raise exceptions[0]
  File "/usr/lib/python3.10/asyncio/base_events.py", line 1049, in create_connection
    sock = await self._connect_sock(
  File "/usr/lib/python3.10/asyncio/base_events.py", line 960, in _connect_sock
    await self.sock_connect(sock, address)
  File "/usr/lib/python3.10/asyncio/selector_events.py", line 500, in sock_connect
    return await fut
  File "/usr/lib/python3.10/asyncio/selector_events.py", line 535, in _sock_connect_cb
    raise OSError(err, f'Connect call failed {address}')
OSError: [Errno 113] Connect call failed ('149.154.167.220', 443)


The above exception was the direct cause of the following exception:

Traceback (most recent call last):
  File "/home/bs/.virtualenvs/telegram/lib/python3.10/site-packages/httpcore/_exceptions.py", line 10, in map_exceptions
    yield
  File "/home/bs/.virtualenvs/telegram/lib/python3.10/site-packages/httpcore/backends/asyncio.py", line 111, in connect_tcp
    stream: anyio.abc.ByteStream = await anyio.connect_tcp(
  File "/home/bs/.virtualenvs/telegram/lib/python3.10/site-packages/anyio/_core/_sockets.py", line 222, in connect_tcp
    raise OSError("All connection attempts failed") from cause
OSError: All connection attempts failed

During handling of the above exception, another exception occurred:

Traceback (most recent call last):
  File "/home/bs/.virtualenvs/telegram/lib/python3.10/site-packages/httpx/_transports/default.py", line 60, in map_httpcore_exceptions
    yield
  File "/home/bs/.virtualenvs/telegram/lib/python3.10/site-packages/httpx/_transports/default.py", line 353, in handle_async_request
    resp = await self._pool.handle_async_request(req)
  File "/home/bs/.virtualenvs/telegram/lib/python3.10/site-packages/httpcore/_async/connection_pool.py", line 253, in handle_async_request
    raise exc
  File "/home/bs/.virtualenvs/telegram/lib/python3.10/site-packages/httpcore/_async/connection_pool.py", line 237, in handle_async_request
    response = await connection.handle_async_request(request)
  File "/home/bs/.virtualenvs/telegram/lib/python3.10/site-packages/httpcore/_async/connection.py", line 86, in handle_async_request
    raise exc
  File "/home/bs/.virtualenvs/telegram/lib/python3.10/site-packages/httpcore/_async/connection.py", line 63, in handle_async_request
    stream = await self._connect(request)
  File "/home/bs/.virtualenvs/telegram/lib/python3.10/site-packages/httpcore/_async/connection.py", line 111, in _connect
    stream = await self._network_backend.connect_tcp(**kwargs)
  File "/home/bs/.virtualenvs/telegram/lib/python3.10/site-packages/httpcore/backends/auto.py", line 29, in connect_tcp
    return await self._backend.connect_tcp(
  File "/home/bs/.virtualenvs/telegram/lib/python3.10/site-packages/httpcore/backends/asyncio.py", line 109, in connect_tcp
    with map_exceptions(exc_map):
  File "/usr/lib/python3.10/contextlib.py", line 153, in __exit__
    self.gen.throw(typ, value, traceback)
  File "/home/bs/.virtualenvs/telegram/lib/python3.10/site-packages/httpcore/_exceptions.py", line 14, in map_exceptions
    raise to_exc(exc)
httpcore.ConnectError: All connection attempts failed

The above exception was the direct cause of the following exception:

Traceback (most recent call last):
  File "/home/bs/.virtualenvs/telegram/lib/python3.10/site-packages/telegram/request/_httpxrequest.py", line 183, in do_request
    res = await self._client.request(
  File "/home/bs/.virtualenvs/telegram/lib/python3.10/site-packages/httpx/_client.py", line 1533, in request
    return await self.send(request, auth=auth, follow_redirects=follow_redirects)
  File "/home/bs/.virtualenvs/telegram/lib/python3.10/site-packages/httpx/_client.py", line 1620, in send
    response = await self._send_handling_auth(
  File "/home/bs/.virtualenvs/telegram/lib/python3.10/site-packages/httpx/_client.py", line 1648, in _send_handling_auth
    response = await self._send_handling_redirects(
  File "/home/bs/.virtualenvs/telegram/lib/python3.10/site-packages/httpx/_client.py", line 1685, in _send_handling_redirects
    response = await self._send_single_request(request)
  File "/home/bs/.virtualenvs/telegram/lib/python3.10/site-packages/httpx/_client.py", line 1722, in _send_single_request
    response = await transport.handle_async_request(request)
  File "/home/bs/.virtualenvs/telegram/lib/python3.10/site-packages/httpx/_transports/default.py", line 352, in handle_async_request
    with map_httpcore_exceptions():
  File "/usr/lib/python3.10/contextlib.py", line 153, in __exit__
    self.gen.throw(typ, value, traceback)
  File "/home/bs/.virtualenvs/telegram/lib/python3.10/site-packages/httpx/_transports/default.py", line 77, in map_httpcore_exceptions
    raise mapped_exc(message) from exc
httpx.ConnectError: All connection attempts failed

The above exception was the direct cause of the following exception:

Traceback (most recent call last):
  File "/home/bs/.virtualenvs/telegram/lib/python3.10/site-packages/telegram/ext/_updater.py", line 600, in _network_loop_retry
    if not await action_cb():
  File "/home/bs/.virtualenvs/telegram/lib/python3.10/site-packages/telegram/ext/_updater.py", line 327, in polling_action_cb
    raise exc
  File "/home/bs/.virtualenvs/telegram/lib/python3.10/site-packages/telegram/ext/_updater.py", line 312, in polling_action_cb
    updates = await self.bot.get_updates(
  File "/home/bs/.virtualenvs/telegram/lib/python3.10/site-packages/telegram/ext/_extbot.py", line 524, in get_updates
    updates = await super().get_updates(
  File "/home/bs/.virtualenvs/telegram/lib/python3.10/site-packages/telegram/_bot.py", line 334, in decorator
    result = await func(*args, **kwargs)  # skipcq: PYL-E1102
  File "/home/bs/.virtualenvs/telegram/lib/python3.10/site-packages/telegram/_bot.py", line 3584, in get_updates
    await self._post(
  File "/home/bs/.virtualenvs/telegram/lib/python3.10/site-packages/telegram/_bot.py", line 422, in _post
    return await self._do_post(
  File "/home/bs/.virtualenvs/telegram/lib/python3.10/site-packages/telegram/ext/_extbot.py", line 306, in _do_post
    return await super()._do_post(
  File "/home/bs/.virtualenvs/telegram/lib/python3.10/site-packages/telegram/_bot.py", line 453, in _do_post
    return await request.post(
  File "/home/bs/.virtualenvs/telegram/lib/python3.10/site-packages/telegram/request/_baserequest.py", line 165, in post
    result = await self._request_wrapper(
  File "/home/bs/.virtualenvs/telegram/lib/python3.10/site-packages/telegram/request/_baserequest.py", line 288, in _request_wrapper
    raise exc
  File "/home/bs/.virtualenvs/telegram/lib/python3.10/site-packages/telegram/request/_baserequest.py", line 274, in _request_wrapper
    code, payload = await self.do_request(
  File "/home/bs/.virtualenvs/telegram/lib/python3.10/site-packages/telegram/request/_httpxrequest.py", line 204, in do_request
    raise NetworkError(f"httpx HTTPError: {err}") from err
telegram.error.NetworkError: httpx HTTPError: All connection attempts failed
Error while getting Updates: httpx HTTPError: All connection attempts failed
No error handlers are registered, logging exception.
anyio._backends._asyncio.ExceptionGroup: 2 exceptions were raised in the task group:
----------------------------
Traceback (most recent call last):
  File "/home/bs/.virtualenvs/telegram/lib/python3.10/site-packages/anyio/_core/_sockets.py", line 164, in try_connect
    stream = await asynclib.connect_tcp(remote_host, remote_port, local_address)
  File "/home/bs/.virtualenvs/telegram/lib/python3.10/site-packages/anyio/_backends/_asyncio.py", line 1691, in connect_tcp
    await get_running_loop().create_connection(
  File "/usr/lib/python3.10/asyncio/base_events.py", line 1064, in create_connection
    raise exceptions[0]
  File "/usr/lib/python3.10/asyncio/base_events.py", line 1049, in create_connection
    sock = await self._connect_sock(
  File "/usr/lib/python3.10/asyncio/base_events.py", line 960, in _connect_sock
    await self.sock_connect(sock, address)
  File "/usr/lib/python3.10/asyncio/selector_events.py", line 500, in sock_connect
    return await fut
  File "/usr/lib/python3.10/asyncio/selector_events.py", line 505, in _sock_connect
    sock.connect(address)
OSError: [Errno 101] Network is unreachable
----------------------------
Traceback (most recent call last):
  File "/home/bs/.virtualenvs/telegram/lib/python3.10/site-packages/anyio/_core/_sockets.py", line 164, in try_connect
    stream = await asynclib.connect_tcp(remote_host, remote_port, local_address)
  File "/home/bs/.virtualenvs/telegram/lib/python3.10/site-packages/anyio/_backends/_asyncio.py", line 1691, in connect_tcp
    await get_running_loop().create_connection(
  File "/usr/lib/python3.10/asyncio/base_events.py", line 1064, in create_connection
    raise exceptions[0]
  File "/usr/lib/python3.10/asyncio/base_events.py", line 1049, in create_connection
    sock = await self._connect_sock(
  File "/usr/lib/python3.10/asyncio/base_events.py", line 960, in _connect_sock
    await self.sock_connect(sock, address)
  File "/usr/lib/python3.10/asyncio/selector_events.py", line 500, in sock_connect
    return await fut
  File "/usr/lib/python3.10/asyncio/selector_events.py", line 535, in _sock_connect_cb
    raise OSError(err, f'Connect call failed {address}')
OSError: [Errno 113] Connect call failed ('149.154.167.220', 443)


The above exception was the direct cause of the following exception:

Traceback (most recent call last):
  File "/home/bs/.virtualenvs/telegram/lib/python3.10/site-packages/httpcore/_exceptions.py", line 10, in map_exceptions
    yield
  File "/home/bs/.virtualenvs/telegram/lib/python3.10/site-packages/httpcore/backends/asyncio.py", line 111, in connect_tcp
    stream: anyio.abc.ByteStream = await anyio.connect_tcp(
  File "/home/bs/.virtualenvs/telegram/lib/python3.10/site-packages/anyio/_core/_sockets.py", line 222, in connect_tcp
    raise OSError("All connection attempts failed") from cause
OSError: All connection attempts failed

During handling of the above exception, another exception occurred:

Traceback (most recent call last):
  File "/home/bs/.virtualenvs/telegram/lib/python3.10/site-packages/httpx/_transports/default.py", line 60, in map_httpcore_exceptions
    yield
  File "/home/bs/.virtualenvs/telegram/lib/python3.10/site-packages/httpx/_transports/default.py", line 353, in handle_async_request
    resp = await self._pool.handle_async_request(req)
  File "/home/bs/.virtualenvs/telegram/lib/python3.10/site-packages/httpcore/_async/connection_pool.py", line 253, in handle_async_request
    raise exc
  File "/home/bs/.virtualenvs/telegram/lib/python3.10/site-packages/httpcore/_async/connection_pool.py", line 237, in handle_async_request
    response = await connection.handle_async_request(request)
  File "/home/bs/.virtualenvs/telegram/lib/python3.10/site-packages/httpcore/_async/connection.py", line 86, in handle_async_request
    raise exc
  File "/home/bs/.virtualenvs/telegram/lib/python3.10/site-packages/httpcore/_async/connection.py", line 63, in handle_async_request
    stream = await self._connect(request)
  File "/home/bs/.virtualenvs/telegram/lib/python3.10/site-packages/httpcore/_async/connection.py", line 111, in _connect
    stream = await self._network_backend.connect_tcp(**kwargs)
  File "/home/bs/.virtualenvs/telegram/lib/python3.10/site-packages/httpcore/backends/auto.py", line 29, in connect_tcp
    return await self._backend.connect_tcp(
  File "/home/bs/.virtualenvs/telegram/lib/python3.10/site-packages/httpcore/backends/asyncio.py", line 109, in connect_tcp
    with map_exceptions(exc_map):
  File "/usr/lib/python3.10/contextlib.py", line 153, in __exit__
    self.gen.throw(typ, value, traceback)
  File "/home/bs/.virtualenvs/telegram/lib/python3.10/site-packages/httpcore/_exceptions.py", line 14, in map_exceptions
    raise to_exc(exc)
httpcore.ConnectError: All connection attempts failed

The above exception was the direct cause of the following exception:

Traceback (most recent call last):
  File "/home/bs/.virtualenvs/telegram/lib/python3.10/site-packages/telegram/request/_httpxrequest.py", line 183, in do_request
    res = await self._client.request(
  File "/home/bs/.virtualenvs/telegram/lib/python3.10/site-packages/httpx/_client.py", line 1533, in request
    return await self.send(request, auth=auth, follow_redirects=follow_redirects)
  File "/home/bs/.virtualenvs/telegram/lib/python3.10/site-packages/httpx/_client.py", line 1620, in send
    response = await self._send_handling_auth(
  File "/home/bs/.virtualenvs/telegram/lib/python3.10/site-packages/httpx/_client.py", line 1648, in _send_handling_auth
    response = await self._send_handling_redirects(
  File "/home/bs/.virtualenvs/telegram/lib/python3.10/site-packages/httpx/_client.py", line 1685, in _send_handling_redirects
    response = await self._send_single_request(request)
  File "/home/bs/.virtualenvs/telegram/lib/python3.10/site-packages/httpx/_client.py", line 1722, in _send_single_request
    response = await transport.handle_async_request(request)
  File "/home/bs/.virtualenvs/telegram/lib/python3.10/site-packages/httpx/_transports/default.py", line 352, in handle_async_request
    with map_httpcore_exceptions():
  File "/usr/lib/python3.10/contextlib.py", line 153, in __exit__
    self.gen.throw(typ, value, traceback)
  File "/home/bs/.virtualenvs/telegram/lib/python3.10/site-packages/httpx/_transports/default.py", line 77, in map_httpcore_exceptions
    raise mapped_exc(message) from exc
httpx.ConnectError: All connection attempts failed

The above exception was the direct cause of the following exception:

Traceback (most recent call last):
  File "/home/bs/.virtualenvs/telegram/lib/python3.10/site-packages/telegram/ext/_updater.py", line 600, in _network_loop_retry
    if not await action_cb():
  File "/home/bs/.virtualenvs/telegram/lib/python3.10/site-packages/telegram/ext/_updater.py", line 327, in polling_action_cb
    raise exc
  File "/home/bs/.virtualenvs/telegram/lib/python3.10/site-packages/telegram/ext/_updater.py", line 312, in polling_action_cb
    updates = await self.bot.get_updates(
  File "/home/bs/.virtualenvs/telegram/lib/python3.10/site-packages/telegram/ext/_extbot.py", line 524, in get_updates
    updates = await super().get_updates(
  File "/home/bs/.virtualenvs/telegram/lib/python3.10/site-packages/telegram/_bot.py", line 334, in decorator
    result = await func(*args, **kwargs)  # skipcq: PYL-E1102
  File "/home/bs/.virtualenvs/telegram/lib/python3.10/site-packages/telegram/_bot.py", line 3584, in get_updates
    await self._post(
  File "/home/bs/.virtualenvs/telegram/lib/python3.10/site-packages/telegram/_bot.py", line 422, in _post
    return await self._do_post(
  File "/home/bs/.virtualenvs/telegram/lib/python3.10/site-packages/telegram/ext/_extbot.py", line 306, in _do_post
    return await super()._do_post(
  File "/home/bs/.virtualenvs/telegram/lib/python3.10/site-packages/telegram/_bot.py", line 453, in _do_post
    return await request.post(
  File "/home/bs/.virtualenvs/telegram/lib/python3.10/site-packages/telegram/request/_baserequest.py", line 165, in post
    result = await self._request_wrapper(
  File "/home/bs/.virtualenvs/telegram/lib/python3.10/site-packages/telegram/request/_baserequest.py", line 288, in _request_wrapper
    raise exc
  File "/home/bs/.virtualenvs/telegram/lib/python3.10/site-packages/telegram/request/_baserequest.py", line 274, in _request_wrapper
    code, payload = await self.do_request(
  File "/home/bs/.virtualenvs/telegram/lib/python3.10/site-packages/telegram/request/_httpxrequest.py", line 204, in do_request
    raise NetworkError(f"httpx HTTPError: {err}") from err
telegram.error.NetworkError: httpx HTTPError: All connection attempts failed
Error while getting Updates: Bad Gateway
No error handlers are registered, logging exception.
Traceback (most recent call last):
  File "/home/bs/.virtualenvs/telegram/lib/python3.10/site-packages/telegram/ext/_updater.py", line 600, in _network_loop_retry
    if not await action_cb():
  File "/home/bs/.virtualenvs/telegram/lib/python3.10/site-packages/telegram/ext/_updater.py", line 327, in polling_action_cb
    raise exc
  File "/home/bs/.virtualenvs/telegram/lib/python3.10/site-packages/telegram/ext/_updater.py", line 312, in polling_action_cb
    updates = await self.bot.get_updates(
  File "/home/bs/.virtualenvs/telegram/lib/python3.10/site-packages/telegram/ext/_extbot.py", line 524, in get_updates
    updates = await super().get_updates(
  File "/home/bs/.virtualenvs/telegram/lib/python3.10/site-packages/telegram/_bot.py", line 334, in decorator
    result = await func(*args, **kwargs)  # skipcq: PYL-E1102
  File "/home/bs/.virtualenvs/telegram/lib/python3.10/site-packages/telegram/_bot.py", line 3584, in get_updates
    await self._post(
  File "/home/bs/.virtualenvs/telegram/lib/python3.10/site-packages/telegram/_bot.py", line 422, in _post
    return await self._do_post(
  File "/home/bs/.virtualenvs/telegram/lib/python3.10/site-packages/telegram/ext/_extbot.py", line 306, in _do_post
    return await super()._do_post(
  File "/home/bs/.virtualenvs/telegram/lib/python3.10/site-packages/telegram/_bot.py", line 453, in _do_post
    return await request.post(
  File "/home/bs/.virtualenvs/telegram/lib/python3.10/site-packages/telegram/request/_baserequest.py", line 165, in post
    result = await self._request_wrapper(
  File "/home/bs/.virtualenvs/telegram/lib/python3.10/site-packages/telegram/request/_baserequest.py", line 332, in _request_wrapper
    raise NetworkError(description or "Bad Gateway")
telegram.error.NetworkError: Bad Gateway
Error while getting Updates: Bad Gateway
No error handlers are registered, logging exception.
Traceback (most recent call last):
  File "/home/bs/.virtualenvs/telegram/lib/python3.10/site-packages/telegram/ext/_updater.py", line 600, in _network_loop_retry
    if not await action_cb():
  File "/home/bs/.virtualenvs/telegram/lib/python3.10/site-packages/telegram/ext/_updater.py", line 327, in polling_action_cb
    raise exc
  File "/home/bs/.virtualenvs/telegram/lib/python3.10/site-packages/telegram/ext/_updater.py", line 312, in polling_action_cb
    updates = await self.bot.get_updates(
  File "/home/bs/.virtualenvs/telegram/lib/python3.10/site-packages/telegram/ext/_extbot.py", line 524, in get_updates
    updates = await super().get_updates(
  File "/home/bs/.virtualenvs/telegram/lib/python3.10/site-packages/telegram/_bot.py", line 334, in decorator
    result = await func(*args, **kwargs)  # skipcq: PYL-E1102
  File "/home/bs/.virtualenvs/telegram/lib/python3.10/site-packages/telegram/_bot.py", line 3584, in get_updates
    await self._post(
  File "/home/bs/.virtualenvs/telegram/lib/python3.10/site-packages/telegram/_bot.py", line 422, in _post
    return await self._do_post(
  File "/home/bs/.virtualenvs/telegram/lib/python3.10/site-packages/telegram/ext/_extbot.py", line 306, in _do_post
    return await super()._do_post(
  File "/home/bs/.virtualenvs/telegram/lib/python3.10/site-packages/telegram/_bot.py", line 453, in _do_post
    return await request.post(
  File "/home/bs/.virtualenvs/telegram/lib/python3.10/site-packages/telegram/request/_baserequest.py", line 165, in post
    result = await self._request_wrapper(
  File "/home/bs/.virtualenvs/telegram/lib/python3.10/site-packages/telegram/request/_baserequest.py", line 332, in _request_wrapper
    raise NetworkError(description or "Bad Gateway")
telegram.error.NetworkError: Bad Gateway
Error while getting Updates: Bad Gateway
No error handlers are registered, logging exception.
Traceback (most recent call last):
  File "/home/bs/.virtualenvs/telegram/lib/python3.10/site-packages/telegram/ext/_updater.py", line 600, in _network_loop_retry
    if not await action_cb():
  File "/home/bs/.virtualenvs/telegram/lib/python3.10/site-packages/telegram/ext/_updater.py", line 327, in polling_action_cb
    raise exc
  File "/home/bs/.virtualenvs/telegram/lib/python3.10/site-packages/telegram/ext/_updater.py", line 312, in polling_action_cb
    updates = await self.bot.get_updates(
  File "/home/bs/.virtualenvs/telegram/lib/python3.10/site-packages/telegram/ext/_extbot.py", line 524, in get_updates
    updates = await super().get_updates(
  File "/home/bs/.virtualenvs/telegram/lib/python3.10/site-packages/telegram/_bot.py", line 334, in decorator
    result = await func(*args, **kwargs)  # skipcq: PYL-E1102
  File "/home/bs/.virtualenvs/telegram/lib/python3.10/site-packages/telegram/_bot.py", line 3584, in get_updates
    await self._post(
  File "/home/bs/.virtualenvs/telegram/lib/python3.10/site-packages/telegram/_bot.py", line 422, in _post
    return await self._do_post(
  File "/home/bs/.virtualenvs/telegram/lib/python3.10/site-packages/telegram/ext/_extbot.py", line 306, in _do_post
    return await super()._do_post(
  File "/home/bs/.virtualenvs/telegram/lib/python3.10/site-packages/telegram/_bot.py", line 453, in _do_post
    return await request.post(
  File "/home/bs/.virtualenvs/telegram/lib/python3.10/site-packages/telegram/request/_baserequest.py", line 165, in post
    result = await self._request_wrapper(
  File "/home/bs/.virtualenvs/telegram/lib/python3.10/site-packages/telegram/request/_baserequest.py", line 332, in _request_wrapper
    raise NetworkError(description or "Bad Gateway")
telegram.error.NetworkError: Bad Gateway
Error while getting Updates: Bad Gateway
No error handlers are registered, logging exception.
Traceback (most recent call last):
  File "/home/bs/.virtualenvs/telegram/lib/python3.10/site-packages/telegram/ext/_updater.py", line 600, in _network_loop_retry
    if not await action_cb():
  File "/home/bs/.virtualenvs/telegram/lib/python3.10/site-packages/telegram/ext/_updater.py", line 327, in polling_action_cb
    raise exc
  File "/home/bs/.virtualenvs/telegram/lib/python3.10/site-packages/telegram/ext/_updater.py", line 312, in polling_action_cb
    updates = await self.bot.get_updates(
  File "/home/bs/.virtualenvs/telegram/lib/python3.10/site-packages/telegram/ext/_extbot.py", line 524, in get_updates
    updates = await super().get_updates(
  File "/home/bs/.virtualenvs/telegram/lib/python3.10/site-packages/telegram/_bot.py", line 334, in decorator
    result = await func(*args, **kwargs)  # skipcq: PYL-E1102
  File "/home/bs/.virtualenvs/telegram/lib/python3.10/site-packages/telegram/_bot.py", line 3584, in get_updates
    await self._post(
  File "/home/bs/.virtualenvs/telegram/lib/python3.10/site-packages/telegram/_bot.py", line 422, in _post
    return await self._do_post(
  File "/home/bs/.virtualenvs/telegram/lib/python3.10/site-packages/telegram/ext/_extbot.py", line 306, in _do_post
    return await super()._do_post(
  File "/home/bs/.virtualenvs/telegram/lib/python3.10/site-packages/telegram/_bot.py", line 453, in _do_post
    return await request.post(
  File "/home/bs/.virtualenvs/telegram/lib/python3.10/site-packages/telegram/request/_baserequest.py", line 165, in post
    result = await self._request_wrapper(
  File "/home/bs/.virtualenvs/telegram/lib/python3.10/site-packages/telegram/request/_baserequest.py", line 332, in _request_wrapper
    raise NetworkError(description or "Bad Gateway")
telegram.error.NetworkError: Bad Gateway
Error while getting Updates: Bad Gateway
No error handlers are registered, logging exception.
Traceback (most recent call last):
  File "/home/bs/.virtualenvs/telegram/lib/python3.10/site-packages/telegram/ext/_updater.py", line 600, in _network_loop_retry
    if not await action_cb():
  File "/home/bs/.virtualenvs/telegram/lib/python3.10/site-packages/telegram/ext/_updater.py", line 327, in polling_action_cb
    raise exc
  File "/home/bs/.virtualenvs/telegram/lib/python3.10/site-packages/telegram/ext/_updater.py", line 312, in polling_action_cb
    updates = await self.bot.get_updates(
  File "/home/bs/.virtualenvs/telegram/lib/python3.10/site-packages/telegram/ext/_extbot.py", line 524, in get_updates
    updates = await super().get_updates(
  File "/home/bs/.virtualenvs/telegram/lib/python3.10/site-packages/telegram/_bot.py", line 334, in decorator
    result = await func(*args, **kwargs)  # skipcq: PYL-E1102
  File "/home/bs/.virtualenvs/telegram/lib/python3.10/site-packages/telegram/_bot.py", line 3584, in get_updates
    await self._post(
  File "/home/bs/.virtualenvs/telegram/lib/python3.10/site-packages/telegram/_bot.py", line 422, in _post
    return await self._do_post(
  File "/home/bs/.virtualenvs/telegram/lib/python3.10/site-packages/telegram/ext/_extbot.py", line 306, in _do_post
    return await super()._do_post(
  File "/home/bs/.virtualenvs/telegram/lib/python3.10/site-packages/telegram/_bot.py", line 453, in _do_post
    return await request.post(
  File "/home/bs/.virtualenvs/telegram/lib/python3.10/site-packages/telegram/request/_baserequest.py", line 165, in post
    result = await self._request_wrapper(
  File "/home/bs/.virtualenvs/telegram/lib/python3.10/site-packages/telegram/request/_baserequest.py", line 332, in _request_wrapper
    raise NetworkError(description or "Bad Gateway")
telegram.error.NetworkError: Bad Gateway
Error while getting Updates: Bad Gateway
No error handlers are registered, logging exception.
Traceback (most recent call last):
  File "/home/bs/.virtualenvs/telegram/lib/python3.10/site-packages/telegram/ext/_updater.py", line 600, in _network_loop_retry
    if not await action_cb():
  File "/home/bs/.virtualenvs/telegram/lib/python3.10/site-packages/telegram/ext/_updater.py", line 327, in polling_action_cb
    raise exc
  File "/home/bs/.virtualenvs/telegram/lib/python3.10/site-packages/telegram/ext/_updater.py", line 312, in polling_action_cb
    updates = await self.bot.get_updates(
  File "/home/bs/.virtualenvs/telegram/lib/python3.10/site-packages/telegram/ext/_extbot.py", line 524, in get_updates
    updates = await super().get_updates(
  File "/home/bs/.virtualenvs/telegram/lib/python3.10/site-packages/telegram/_bot.py", line 334, in decorator
    result = await func(*args, **kwargs)  # skipcq: PYL-E1102
  File "/home/bs/.virtualenvs/telegram/lib/python3.10/site-packages/telegram/_bot.py", line 3584, in get_updates
    await self._post(
  File "/home/bs/.virtualenvs/telegram/lib/python3.10/site-packages/telegram/_bot.py", line 422, in _post
    return await self._do_post(
  File "/home/bs/.virtualenvs/telegram/lib/python3.10/site-packages/telegram/ext/_extbot.py", line 306, in _do_post
    return await super()._do_post(
  File "/home/bs/.virtualenvs/telegram/lib/python3.10/site-packages/telegram/_bot.py", line 453, in _do_post
    return await request.post(
  File "/home/bs/.virtualenvs/telegram/lib/python3.10/site-packages/telegram/request/_baserequest.py", line 165, in post
    result = await self._request_wrapper(
  File "/home/bs/.virtualenvs/telegram/lib/python3.10/site-packages/telegram/request/_baserequest.py", line 332, in _request_wrapper
    raise NetworkError(description or "Bad Gateway")
telegram.error.NetworkError: Bad Gateway
Error while getting Updates: Bad Gateway
No error handlers are registered, logging exception.
Traceback (most recent call last):
  File "/home/bs/.virtualenvs/telegram/lib/python3.10/site-packages/telegram/ext/_updater.py", line 600, in _network_loop_retry
    if not await action_cb():
  File "/home/bs/.virtualenvs/telegram/lib/python3.10/site-packages/telegram/ext/_updater.py", line 327, in polling_action_cb
    raise exc
  File "/home/bs/.virtualenvs/telegram/lib/python3.10/site-packages/telegram/ext/_updater.py", line 312, in polling_action_cb
    updates = await self.bot.get_updates(
  File "/home/bs/.virtualenvs/telegram/lib/python3.10/site-packages/telegram/ext/_extbot.py", line 524, in get_updates
    updates = await super().get_updates(
  File "/home/bs/.virtualenvs/telegram/lib/python3.10/site-packages/telegram/_bot.py", line 334, in decorator
    result = await func(*args, **kwargs)  # skipcq: PYL-E1102
  File "/home/bs/.virtualenvs/telegram/lib/python3.10/site-packages/telegram/_bot.py", line 3584, in get_updates
    await self._post(
  File "/home/bs/.virtualenvs/telegram/lib/python3.10/site-packages/telegram/_bot.py", line 422, in _post
    return await self._do_post(
  File "/home/bs/.virtualenvs/telegram/lib/python3.10/site-packages/telegram/ext/_extbot.py", line 306, in _do_post
    return await super()._do_post(
  File "/home/bs/.virtualenvs/telegram/lib/python3.10/site-packages/telegram/_bot.py", line 453, in _do_post
    return await request.post(
  File "/home/bs/.virtualenvs/telegram/lib/python3.10/site-packages/telegram/request/_baserequest.py", line 165, in post
    result = await self._request_wrapper(
  File "/home/bs/.virtualenvs/telegram/lib/python3.10/site-packages/telegram/request/_baserequest.py", line 332, in _request_wrapper
    raise NetworkError(description or "Bad Gateway")
telegram.error.NetworkError: Bad Gateway
Error while getting Updates: Bad Gateway
No error handlers are registered, logging exception.
Traceback (most recent call last):
  File "/home/bs/.virtualenvs/telegram/lib/python3.10/site-packages/telegram/ext/_updater.py", line 600, in _network_loop_retry
    if not await action_cb():
  File "/home/bs/.virtualenvs/telegram/lib/python3.10/site-packages/telegram/ext/_updater.py", line 327, in polling_action_cb
    raise exc
  File "/home/bs/.virtualenvs/telegram/lib/python3.10/site-packages/telegram/ext/_updater.py", line 312, in polling_action_cb
    updates = await self.bot.get_updates(
  File "/home/bs/.virtualenvs/telegram/lib/python3.10/site-packages/telegram/ext/_extbot.py", line 524, in get_updates
    updates = await super().get_updates(
  File "/home/bs/.virtualenvs/telegram/lib/python3.10/site-packages/telegram/_bot.py", line 334, in decorator
    result = await func(*args, **kwargs)  # skipcq: PYL-E1102
  File "/home/bs/.virtualenvs/telegram/lib/python3.10/site-packages/telegram/_bot.py", line 3584, in get_updates
    await self._post(
  File "/home/bs/.virtualenvs/telegram/lib/python3.10/site-packages/telegram/_bot.py", line 422, in _post
    return await self._do_post(
  File "/home/bs/.virtualenvs/telegram/lib/python3.10/site-packages/telegram/ext/_extbot.py", line 306, in _do_post
    return await super()._do_post(
  File "/home/bs/.virtualenvs/telegram/lib/python3.10/site-packages/telegram/_bot.py", line 453, in _do_post
    return await request.post(
  File "/home/bs/.virtualenvs/telegram/lib/python3.10/site-packages/telegram/request/_baserequest.py", line 165, in post
    result = await self._request_wrapper(
  File "/home/bs/.virtualenvs/telegram/lib/python3.10/site-packages/telegram/request/_baserequest.py", line 332, in _request_wrapper
    raise NetworkError(description or "Bad Gateway")
telegram.error.NetworkError: Bad Gateway
No error handlers are registered, logging exception.
Traceback (most recent call last):
  File "/home/bs/.virtualenvs/telegram/lib/python3.10/site-packages/telegram/ext/_application.py", line 1063, in process_update
    await coroutine
  File "/home/bs/.virtualenvs/telegram/lib/python3.10/site-packages/telegram/ext/_handler.py", line 141, in handle_update
    return await self.callback(update, context)
  File "/home/bs/python-scripts/telegram-bot/bot.py", line 72, in send_translate
    message = translate(replied_to.text)
  File "/home/bs/python-scripts/telegram-bot/translate.py", line 11, in translate
    return translator.translate(text)
  File "/home/bs/.virtualenvs/telegram/lib/python3.10/site-packages/deep_translator/google.py", line 55, in translate
    if is_input_valid(text):
  File "/home/bs/.virtualenvs/telegram/lib/python3.10/site-packages/deep_translator/validate.py", line 18, in is_input_valid
    raise NotValidPayload(text)
deep_translator.exceptions.NotValidPayload: None --> text must be a valid text with maximum 5000 character, otherwise it cannot be translated
/home/bs/python-scripts/telegram-bot/bot.py:66: RuntimeWarning: coroutine 'Message.reply_text' was never awaited
  update.message.reply_text("You have to reply to a message for me to translate",
RuntimeWarning: Enable tracemalloc to get the object allocation traceback
